Workbook

Sheet Report >>

Sheet Executive_Summary
B2: ='2023 Control'!$C$3 -> Concertiv
B3: =('2024 Control'!$C$4)&" Reporting Package" -> December 2025 Reporting Package
B4: Executive Summary
C5: What Went Well | D5: What Did Not Go Well | E5: Focus Areas for next month
B6: Finance | C6: - Collections improved particularly in Feb after new proccess set up with New Logo Sales + CS - Multiple 3 year deals signed, as well as other renewals - Vinay joined the team in Dec and is coming up to speed | D6: - Signficant Churn in the month (known), with more in Feb - Alpha Quest going out of business increased churn later in the year - No budget, OKRs or bonuses set given Shane's departure - Only $5k of new logo from one small PortCo | E6: - Finalizing Budget, OKRs, Comp Plans, BoD Deck - Finishing onboarding of Carta / 409A valuation
B7: Product - Development | C7: * Client Portal (MVP) was rolled out to the Cohort 0 clients. The team did a great job of responding to beta testing feedback and resolving issues. Great cross-functional collaboration during customer-facing demos. * Launched support for Navan Data Ingestion (Hotel) | D7: * Still plagued by Power BI reporting issues occurring due to configurations belonging to Jennifer W. that were not transitioned from her local machine. | E7: * Hotel Directory in Client Portal -- in progress * Rategain Data Ingestion -- in progress * Market Data Reporting and Notifications in Client Portal -- in progress * Seat-based Cost Allocation -- in progress * Market Data enhancements ready to be deployed -- (1) Fast availability of data hygiene reports to proactively audit, QC 360 and to prevent managed service breaches; (2) Incorporate automation of elementary QC checks for Managed Services to prevent further service breaches * Team is switching to Agentic AI development methods. Expect shorter build cycles and more indepth product discovery.
B8: Product - D&T | C8: -No missed renewals to clients, no breaches on Managed Services -Product Roadmap finalized for H1 -Development plans in place for all team members -Positioning statements and OKRs took significant steps forward -Attended 16 client meetings | D8: -Many conversations about OKRs with little progress -Ambiguity about value creation / metric tracking -Quality of life issues with C360 impacting daily tasks -Partnership conversations have mixed initial results at best | E8: Finalizing 2025 bonuses, outlining 2026 bonus framework Ensuring content from the Insights Factory is irresistible Data cleanse launch Salary & title architecture
B9: Product - Travel | C9: - Hotel Directory progressing quickly, due in part to engineers exploring AI tools - Internal alignment on ICP - Agreement to share Nishant's capacity in IND with Insights Team | D9: - Slow hiring process to backfill in NY + IND leading to capacity constraints - Positioning statement + collateral incomplete; creating material for pitches remains manual - Reporting still manual and ad hoc - Lack of KPIs | E9: - Transitioning Jen's work to rest of team (American deal, Avis deal, Reporting) - Feedback and testing for hotel directory - Hiring & onboarding new SME - Prioritizing key partnerships (TMCs, Navan, Concur) - Onboard Nishant
B10: Sales & Marketing | C10: - PEI Conference (6+ referrals) / Video interview - Global Alts Miami (client visits + partner activation) - C-Suite Dinner (10 senior client stakeholders) - Sales distribution (CWAN/ IQ EQ) - Veritas Enterprise PortCo / Brown Advisory / early GP prospects | D10: - Jordan Lee last day 3/6 - Positioning statement delivery - collateral delay - Pipeline cleanup/ pivot to refreshed ICP - Lack of client messaging regarding CEO tranition | E10: - Deal focus- Vertias & Brown Advisory - Revamped collateral/ website/ explainer video - March 12th Concertiv Sunset Series kick-off - March 16h IQ EQ joint diner / CWAN + IQ EQ activation
B11: Customer Success | C11: - Audax renewed for 3 years 5% increase y/y - Norwest renewed for 3 years CPI+5% increase y/y - AmSec Travel renewed $50k -> $65k - Hamilton Lane in-person reset | D11: - Lack of RevOps has caused data hygeine issues and slowed PowerBI updates - Fewer AA-joined client meetings between performance reviews, MDAs - Bonus delays + Shane exit | E11: - Morale is so so. Focused on team engagement. - Quinbrook exec alignment as blueprint for roadshow

Sheet Sprints_Special_Projects
B2: [PortCo Name]
B3: [Month] [Year] Reporting Package
B4: Sprints / Special Projects

Sheet Prod Dev
B2: ='2023 Control'!$C$3 -> Concertiv
B3: =('2024 Control'!$C$4)&" Reporting Package" -> December 2025 Reporting Package
B4: Product Development
E5: Monthly | BB5: 1 | BF5: 2 | BJ5: 3 | BN5: 4 | BR5: YTD vs. Budget
D6: Units | E6: 44957 | F6: 44985 | G6: 45016 | H6: =EOMONTH(G6,1) -> 45046 | I6: =EOMONTH(H6,1) -> 45077 | J6: =EOMONTH(I6,1) -> 45107 | K6: =EOMONTH(J6,1) -> 45138 | L6: =EOMONTH(K6,1) -> 45169 | M6: =EOMONTH(L6,1) -> 45199 | N6: =EOMONTH(M6,1) -> 45230 | O6: =EOMONTH(N6,1) -> 45260 | ... AZ6: =EOMONTH(AY6,1) -> 46387 | BB6: Act | BC6: Bgt. | BD6: Diff. | BF6: Act | BG6: Bgt. | BH6: Diff. | BJ6: Act | BK6: Bgt. | BL6: Diff. | BN6: Act | BO6: Bgt. | BP6: Diff. | BR6: YTD | BS6: Bgt. | BT6: Diff. | BV6: LTM
BB7: Q1 | BF7: Q2 | BJ7: Q3 | BN7: Q4
B8: Squads
B9: # of Squads | C9: EoP | D9: =VLOOKUP($B$4&" "&$B9,Actuals!$D$4:$AG$131,3,FALSE) -> # | E9: {=_xlfn.XLOOKUP( $B$4&" "&$B9, Actuals!$D:$D, _xlfn.XLOOKUP( E$6, Actuals!$H$3:$BD$3, Actuals!$H:$BD ) )} -> 2 | F9: {=_xlfn.XLOOKUP( $B$4&" "&$B9, Actuals!$D:$D, _xlfn.XLOOKUP( F$6, Actuals!$H$3:$BD$3, Actuals!$H:$BD ) )} -> 2 | G9: {=_xlfn.XLOOKUP( $B$4&" "&$B9, Actuals!$D:$D, _xlfn.XLOOKUP( G$6, Actuals!$H$3:$BD$3, Actuals!$H:$BD ) )} -> 2 | H9: {=_xlfn.XLOOKUP( $B$4&" "&$B9, Actuals!$D:$D, _xlfn.XLOOKUP( H$6, Actuals!$H$3:$BD$3, Actuals!$H:$BD ) )} -> 2 | I9: {=_xlfn.XLOOKUP( $B$4&" "&$B9, Actuals!$D:$D, _xlfn.XLOOKUP( I$6, Actuals!$H$3:$BD$3, Actuals!$H:$BD ) )} -> 2 | J9: {=_xlfn.XLOOKUP( $B$4&" "&$B9, Actuals!$D:$D, _xlfn.XLOOKUP( J$6, Actuals!$H$3:$BD$3, Actuals!$H:$BD ) )} -> 2 | K9: {=_xlfn.XLOOKUP( $B$4&" "&$B9, Actuals!$D:$D, _xlfn.XLOOKUP( K$6, Actuals!$H$3:$BD$3, Actuals!$H:$BD ) )} -> 3 | L9: {=_xlfn.XLOOKUP( $B$4&" "&$B9, Actuals!$D:$D, _xlfn.XLOOKUP( L$6, Actuals!$H$3:$BD$3, Actuals!$H:$BD ) )} -> 3 | ... AZ9: {=_xlfn.XLOOKUP( $B$4&" "&$B9, Actuals!$D:$D, _xlfn.XLOOKUP( AZ$6, Actuals!$H$3:$BD$3, Actuals!$H:$BD ) )} -> 0 | BB9: {=_xlfn.XLOOKUP( $B$4&" "&$B9, Actuals!$D:$D, _xlfn.XLOOKUP( BB$7, Actuals!$H$3:$BM$3, Actuals!$H:$BM ) )} -> 3 | BC9: =VLOOKUP($B$4&" "&$B9,Budget!$AG$4:$AL$132,$BB$5+1,FALSE) -> 3 | BD9: =BB9-BC9 -> 0 | BF9: {=_xlfn.XLOOKUP( $B$4&" "&$B9, Actuals!$D:$D, _xlfn.XLOOKUP( BF$7, Actuals!$H$3:$BM$3, Actuals!$H:$BM ) )} -> - | BG9: =VLOOKUP($B$4&" "&$B9,Budget!$AG$4:$AL$132,BF$5+1,FALSE) -> 3 | BH9: =BF9-BG9 -> #VALUE! | BJ9: {=_xlfn.XLOOKUP( $B$4&" "&$B9, Actuals!$D:$D, _xlfn.XLOOKUP( BJ$7, Actuals!$H$3:$BM$3, Actuals!$H:$BM ) )} -> - | BK9: =VLOOKUP($B$4&" "&$B9,Budget!$AG$4:$AL$132,BJ$5+1,FALSE) -> 3 | BL9: =BJ9-BK9 -> #VALUE! | BN9: {=_xlfn.XLOOKUP( $B$4&" "&$B9, Actuals!$D:$D, _xlfn.XLOOKUP( BN$7, Actuals!$H$3:$BM$3, Actuals!$H:$BM ) )} -> - | BO9: =VLOOKUP($B$4&" "&$B9,Budget!$AG$4:$AL$132,BN$5+1,FALSE) -> 3 | BR9: {=_xlfn.XLOOKUP( $B$4&" "&$B9, Actuals!$D:$D, _xlfn.XLOOKUP( BR$6, Actuals!$H$3:$BM$3, Actuals!$H:$BM ) )} -> 0.75 | BS9: =VLOOKUP($B$4&" "&$B9,Budget!$AG$4:$AL$132,6,FALSE) -> 3 | BT9: =IFERROR(BR9-BS9,"-") -> -2.25 | BV9: {=_xlfn.XLOOKUP( $B$4&" "&$B9, Actuals!$D:$D, _xlfn.XLOOKUP( BV$6, Actuals!$H$3:$BM$3, Actuals!$H:$BM ) )} -> 2.5
B10: # of Sprints | C10: In-period | D10: =VLOOKUP($B$4&" "&$B10,Actuals!$D$4:$AG$131,3,FALSE) -> # | E10: {=_xlfn.XLOOKUP( $B$4&" "&$B10, Actuals!$D:$D, _xlfn.XLOOKUP( E$6, Actuals!$H$3:$BD$3, Actuals!$H:$BD ) )} -> 4 | F10: {=_xlfn.XLOOKUP( $B$4&" "&$B10, Actuals!$D:$D, _xlfn.XLOOKUP( F$6, Actuals!$H$3:$BD$3, Actuals!$H:$BD ) )} -> 4 | G10: {=_xlfn.XLOOKUP( $B$4&" "&$B10, Actuals!$D:$D, _xlfn.XLOOKUP( G$6, Actuals!$H$3:$BD$3, Actuals!$H:$BD ) )} -> 4 | H10: {=_xlfn.XLOOKUP( $B$4&" "&$B10, Actuals!$D:$D, _xlfn.XLOOKUP( H$6, Actuals!$H$3:$BD$3, Actuals!$H:$BD ) )} -> 2 | I10: {=_xlfn.XLOOKUP( $B$4&" "&$B10, Actuals!$D:$D, _xlfn.XLOOKUP( I$6, Actuals!$H$3:$BD$3, Actuals!$H:$BD ) )} -> 2.2 | J10: {=_xlfn.XLOOKUP( $B$4&" "&$B10, Actuals!$D:$D, _xlfn.XLOOKUP( J$6, Actuals!$H$3:$BD$3, Actuals!$H:$BD ) )} -> 2 | K10: {=_xlfn.XLOOKUP( $B$4&" "&$B10, Actuals!$D:$D, _xlfn.XLOOKUP( K$6, Actuals!$H$3:$BD$3, Actuals!$H:$BD ) )} -> 2 | L10: {=_xlfn.XLOOKUP( $B$4&" "&$B10, Actuals!$D:$D, _xlfn.XLOOKUP( L$6, Actuals!$H$3:$BD$3, Actuals!$H:$BD ) )} -> 2 | ... AZ10: {=_xlfn.XLOOKUP( $B$4&" "&$B10, Actuals!$D:$D, _xlfn.XLOOKUP( AZ$6, Actuals!$H$3:$BD$3, Actuals!$H:$BD ) )} -> 0 | BB10: {=_xlfn.XLOOKUP( $B$4&" "&$B10, Actuals!$D:$D, _xlfn.XLOOKUP( BB$7, Actuals!$H$3:$BM$3, Actuals!$H:$BM ) )} -> 6 | BC10: =VLOOKUP($B$4&" "&$B10,Budget!$AG$4:$AL$132,$BB$5+1,FALSE) -> 6 | BD10: =BB10-BC10 -> 0 | BF10: {=_xlfn.XLOOKUP( $B$4&" "&$B10, Actuals!$D:$D, _xlfn.XLOOKUP( BF$7, Actuals!$H$3:$BM$3, Actuals!$H:$BM ) )} -> 0 | BG10: =VLOOKUP($B$4&" "&$B10,Budget!$AG$4:$AL$132,BF$5+1,FALSE) -> 6 | BH10: =BF10-BG10 -> -6 | BJ10: {=_xlfn.XLOOKUP( $B$4&" "&$B10, Actuals!$D:$D, _xlfn.XLOOKUP( BJ$7, Actuals!$H$3:$BM$3, Actuals!$H:$BM ) )} -> 0 | BK10: =VLOOKUP($B$4&" "&$B10,Budget!$AG$4:$AL$132,BJ$5+1,FALSE) -> 6 | BL10: =BJ10-BK10 -> -6 | BN10: {=_xlfn.XLOOKUP( $B$4&" "&$B10, Actuals!$D:$D, _xlfn.XLOOKUP( BN$7, Actuals!$H$3:$BM$3, Actuals!$H:$BM ) )} -> 0 | BO10: =VLOOKUP($B$4&" "&$B10,Budget!$AG$4:$AL$132,BN$5+1,FALSE) -> 6 | BR10: {=_xlfn.XLOOKUP( $B$4&" "&$B10, Actuals!$D:$D, _xlfn.XLOOKUP( BR$6, Actuals!$H$3:$BM$3, Actuals!$H:$BM ) )} -> 6 | BS10: =VLOOKUP($B$4&" "&$B10,Budget!$AG$4:$AL$132,6,FALSE) -> 24 | BT10: =IFERROR(BR10-BS10,"-") -> -18 | BV10: =VLOOKUP($B$4&" "&$B10,Actuals!$BG$4:$BM$131,7,FALSE) -> 24
B12: Production
B13: Story Points Committed | C13: In-period | D13: =VLOOKUP($B$4&" "&$B13,Actuals!$D$4:$AG$131,3,FALSE) -> # | E13: {=_xlfn.XLOOKUP( $B$4&" "&$B13, Actuals!$D:$D, _xlfn.XLOOKUP( E$6, Actuals!$H$3:$BD$3, Actuals!$H:$BD ) )} -> 220 | F13: {=_xlfn.XLOOKUP( $B$4&" "&$B13, Actuals!$D:$D, _xlfn.XLOOKUP( F$6, Actuals!$H$3:$BD$3, Actuals!$H:$BD ) )} -> 159 | G13: {=_xlfn.XLOOKUP( $B$4&" "&$B13, Actuals!$D:$D, _xlfn.XLOOKUP( G$6, Actuals!$H$3:$BD$3, Actuals!$H:$BD ) )} -> 196 | H13: {=_xlfn.XLOOKUP( $B$4&" "&$B13, Actuals!$D:$D, _xlfn.XLOOKUP( H$6, Actuals!$H$3:$BD$3, Actuals!$H:$BD ) )} -> 115 | I13: {=_xlfn.XLOOKUP( $B$4&" "&$B13, Actuals!$D:$D, _xlfn.XLOOKUP( I$6, Actuals!$H$3:$BD$3, Actuals!$H:$BD ) )} -> 265 | J13: {=_xlfn.XLOOKUP( $B$4&" "&$B13, Actuals!$D:$D, _xlfn.XLOOKUP( J$6, Actuals!$H$3:$BD$3, Actuals!$H:$BD ) )} -> 223 | K13: {=_xlfn.XLOOKUP( $B$4&" "&$B13, Actuals!$D:$D, _xlfn.XLOOKUP( K$6, Actuals!$H$3:$BD$3, Actuals!$H:$BD ) )} -> 234 | L13: {=_xlfn.XLOOKUP( $B$4&" "&$B13, Actuals!$D:$D, _xlfn.XLOOKUP( L$6, Actuals!$H$3:$BD$3, Actuals!$H:$BD ) )} -> 328 | ... AZ13: {=_xlfn.XLOOKUP( $B$4&" "&$B13, Actuals!$D:$D, _xlfn.XLOOKUP( AZ$6, Actuals!$H$3:$BD$3, Actuals!$H:$BD ) )} -> 0 | BB13: {=_xlfn.XLOOKUP( $B$4&" "&$B13, Actuals!$D:$D, _xlfn.XLOOKUP( BB$7, Actuals!$H$3:$BM$3, Actuals!$H:$BM ) )} -> 391 | BC13: =VLOOKUP($B$4&" "&$B13,Budget!$AG$4:$AL$132,$BB$5+1,FALSE) -> 702 | BD13: =BB13-BC13 -> -311 | BF13: {=_xlfn.XLOOKUP( $B$4&" "&$B13, Actuals!$D:$D, _xlfn.XLOOKUP( BF$7, Actuals!$H$3:$BM$3, Actuals!$H:$BM ) )} -> 0 | BG13: =VLOOKUP($B$4&" "&$B13,Budget!$AG$4:$AL$132,BF$5+1,FALSE) -> 773.5 | BH13: =BF13-BG13 -> -773.5 | BJ13: {=_xlfn.XLOOKUP( $B$4&" "&$B13, Actuals!$D:$D, _xlfn.XLOOKUP( BJ$7, Actuals!$H$3:$BM$3, Actuals!$H:$BM ) )} -> 0 | BK13: =VLOOKUP($B$4&" "&$B13,Budget!$AG$4:$AL$132,BJ$5+1,FALSE) -> 821.16667 | BL13: =BJ13-BK13 -> -821.16667 | BN13: {=_xlfn.XLOOKUP( $B$4&" "&$B13, Actuals!$D:$D, _xlfn.XLOOKUP( BN$7, Actuals!$H$3:$BM$3, Actuals!$H:$BM ) )} -> 0 | BO13: =VLOOKUP($B$4&" "&$B13,Budget!$AG$4:$AL$132,BN$5+1,FALSE) -> 929.5 | BR13: {=_xlfn.XLOOKUP( $B$4&" "&$B13, Actuals!$D:$D, _xlfn.XLOOKUP( BR$6, Actuals!$H$3:$BM$3, Actuals!$H:$BM ) )} -> 391 | BS13: =VLOOKUP($B$4&" "&$B13,Budget!$AG$4:$AL$132,6,FALSE) -> 3250 | BT13: =IFERROR(BR13-BS13,"-") -> -2859 | BV13: {=_xlfn.XLOOKUP( $B$4&" "&$B13, Actuals!$D:$D, _xlfn.XLOOKUP( BV$6, Actuals!$H$3:$BM$3, Actuals!$H:$BM ) )} -> 3998
B14: Story Points Completed | C14: In-period | D14: =VLOOKUP($B$4&" "&$B14,Actuals!$D$4:$AG$131,3,FALSE) -> # | E14: {=_xlfn.XLOOKUP( $B$4&" "&$B14, Actuals!$D:$D, _xlfn.XLOOKUP( E$6, Actuals!$H$3:$BD$3, Actuals!$H:$BD ) )} -> 139 | F14: {=_xlfn.XLOOKUP( $B$4&" "&$B14, Actuals!$D:$D, _xlfn.XLOOKUP( F$6, Actuals!$H$3:$BD$3, Actuals!$H:$BD ) )} -> 185 | G14: {=_xlfn.XLOOKUP( $B$4&" "&$B14, Actuals!$D:$D, _xlfn.XLOOKUP( G$6, Actuals!$H$3:$BD$3, Actuals!$H:$BD ) )} -> 117 | H14: {=_xlfn.XLOOKUP( $B$4&" "&$B14, Actuals!$D:$D, _xlfn.XLOOKUP( H$6, Actuals!$H$3:$BD$3, Actuals!$H:$BD ) )} -> 262 | I14: {=_xlfn.XLOOKUP( $B$4&" "&$B14, Actuals!$D:$D, _xlfn.XLOOKUP( I$6, Actuals!$H$3:$BD$3, Actuals!$H:$BD ) )} -> 136 | J14: {=_xlfn.XLOOKUP( $B$4&" "&$B14, Actuals!$D:$D, _xlfn.XLOOKUP( J$6, Actuals!$H$3:$BD$3, Actuals!$H:$BD ) )} -> 164 | K14: {=_xlfn.XLOOKUP( $B$4&" "&$B14, Actuals!$D:$D, _xlfn.XLOOKUP( K$6, Actuals!$H$3:$BD$3, Actuals!$H:$BD ) )} -> 142 | L14: {=_xlfn.XLOOKUP( $B$4&" "&$B14, Actuals!$D:$D, _xlfn.XLOOKUP( L$6, Actuals!$H$3:$BD$3, Actuals!$H:$BD ) )} -> 115 | ... AZ14: {=_xlfn.XLOOKUP( $B$4&" "&$B14, Actuals!$D:$D, _xlfn.XLOOKUP( AZ$6, Actuals!$H$3:$BD$3, Actuals!$H:$BD ) )} -> 0 | BB14: {=_xlfn.XLOOKUP( $B$4&" "&$B14, Actuals!$D:$D, _xlfn.XLOOKUP( BB$7, Actuals!$H$3:$BM$3, Actuals!$H:$BM ) )} -> 350 | BC14: =VLOOKUP($B$4&" "&$B14,Budget!$AG$4:$AL$132,$BB$5+1,FALSE) -> 0 | BD14: =BB14-BC14 -> 350 | BF14: {=_xlfn.XLOOKUP( $B$4&" "&$B14, Actuals!$D:$D, _xlfn.XLOOKUP( BF$7, Actuals!$H$3:$BM$3, Actuals!$H:$BM ) )} -> 0 | BG14: =VLOOKUP($B$4&" "&$B14,Budget!$AG$4:$AL$132,BF$5+1,FALSE) -> 0 | BH14: =BF14-BG14 -> 0 | BJ14: {=_xlfn.XLOOKUP( $B$4&" "&$B14, Actuals!$D:$D, _xlfn.XLOOKUP( BJ$7, Actuals!$H$3:$BM$3, Actuals!$H:$BM ) )} -> 0 | BK14: =VLOOKUP($B$4&" "&$B14,Budget!$AG$4:$AL$132,BJ$5+1,FALSE) -> 0 | BL14: =BJ14-BK14 -> 0 | BN14: {=_xlfn.XLOOKUP( $B$4&" "&$B14, Actuals!$D:$D, _xlfn.XLOOKUP( BN$7, Actuals!$H$3:$BM$3, Actuals!$H:$BM ) )} -> 0 | BO14: =VLOOKUP($B$4&" "&$B14,Budget!$AG$4:$AL$132,BN$5+1,FALSE) -> 0 | BR14: {=_xlfn.XLOOKUP( $B$4&" "&$B14, Actuals!$D:$D, _xlfn.XLOOKUP( BR$6, Actuals!$H$3:$BM$3, Actuals!$H:$BM ) )} -> 350 | BS14: =VLOOKUP($B$4&" "&$B14,Budget!$AG$4:$AL$132,6,FALSE) -> 0 | BT14: =IFERROR(BR14-BS14,"-") -> 350 | BV14: {=_xlfn.XLOOKUP( $B$4&" "&$B14, Actuals!$D:$D, _xlfn.XLOOKUP( BV$6, Actuals!$H$3:$BM$3, Actuals!$H:$BM ) )} -> 3610
B15: % Completed | C15: In-period | D15: =VLOOKUP($B$4&" "&$B15,Actuals!$D$4:$AG$131,3,FALSE) -> % | E15: {=_xlfn.XLOOKUP( $B$4&" "&$B15, Actuals!$D:$D, _xlfn.XLOOKUP( E$6, Actuals!$H$3:$BD$3, Actuals!$H:$BD ) )} -> 0.63181818 | F15: {=_xlfn.XLOOKUP( $B$4&" "&$B15, Actuals!$D:$D, _xlfn.XLOOKUP( F$6, Actuals!$H$3:$BD$3, Actuals!$H:$BD ) )} -> 1.163522 | G15: {=_xlfn.XLOOKUP( $B$4&" "&$B15, Actuals!$D:$D, _xlfn.XLOOKUP( G$6, Actuals!$H$3:$BD$3, Actuals!$H:$BD ) )} -> 0.59693878 | H15: {=_xlfn.XLOOKUP( $B$4&" "&$B15, Actuals!$D:$D, _xlfn.XLOOKUP( H$6, Actuals!$H$3:$BD$3, Actuals!$H:$BD ) )} -> 2.2782609 | I15: {=_xlfn.XLOOKUP( $B$4&" "&$B15, Actuals!$D:$D, _xlfn.XLOOKUP( I$6, Actuals!$H$3:$BD$3, Actuals!$H:$BD ) )} -> 0.51320755 | J15: {=_xlfn.XLOOKUP( $B$4&" "&$B15, Actuals!$D:$D, _xlfn.XLOOKUP( J$6, Actuals!$H$3:$BD$3, Actuals!$H:$BD ) )} -> 0.73542601 | K15: {=_xlfn.XLOOKUP( $B$4&" "&$B15, Actuals!$D:$D, _xlfn.XLOOKUP( K$6, Actuals!$H$3:$BD$3, Actuals!$H:$BD ) )} -> 0.60683761 | L15: {=_xlfn.XLOOKUP( $B$4&" "&$B15, Actuals!$D:$D, _xlfn.XLOOKUP( L$6, Actuals!$H$3:$BD$3, Actuals!$H:$BD ) )} -> 0.35060976 | ... AZ15: {=_xlfn.XLOOKUP( $B$4&" "&$B15, Actuals!$D:$D, _xlfn.XLOOKUP( AZ$6, Actuals!$H$3:$BD$3, Actuals!$H:$BD ) )} | BB15: {=_xlfn.XLOOKUP( $B$4&" "&$B15, Actuals!$D:$D, _xlfn.XLOOKUP( BB$7, Actuals!$H$3:$BM$3, Actuals!$H:$BM ) )} -> 0.89514066 | BC15: =VLOOKUP($B$4&" "&$B15,Budget!$AG$4:$AL$132,$BB$5+1,FALSE) -> 0 | BD15: =IFERROR(BB15-BC15,"-") -> 0.89514066 | BF15: {=_xlfn.XLOOKUP( $B$4&" "&$B15, Actuals!$D:$D, _xlfn.XLOOKUP( BF$7, Actuals!$H$3:$BM$3, Actuals!$H:$BM ) )} -> - | BG15: =VLOOKUP($B$4&" "&$B15,Budget!$AG$4:$AL$132,BF$5+1,FALSE) -> 0 | BH15: =IFERROR(BF15-BG15,"-") -> - | BJ15: {=_xlfn.XLOOKUP( $B$4&" "&$B15, Actuals!$D:$D, _xlfn.XLOOKUP( BJ$7, Actuals!$H$3:$BM$3, Actuals!$H:$BM ) )} -> - | BK15: =VLOOKUP($B$4&" "&$B15,Budget!$AG$4:$AL$132,BJ$5+1,FALSE) -> 0 | BL15: =IFERROR(BJ15-BK15,"-") -> - | BN15: {=_xlfn.XLOOKUP( $B$4&" "&$B15, Actuals!$D:$D, _xlfn.XLOOKUP( BN$7, Actuals!$H$3:$BM$3, Actuals!$H:$BM ) )} -> - | BO15: =VLOOKUP($B$4&" "&$B15,Budget!$AG$4:$AL$132,BN$5+1,FALSE) -> 0 | BR15: {=_xlfn.XLOOKUP( $B$4&" "&$B15, Actuals!$D:$D, _xlfn.XLOOKUP( BR$6, Actuals!$H$3:$BM$3, Actuals!$H:$BM ) )} -> 0.89514066 | BS15: =VLOOKUP($B$4&" "&$B15,Budget!$AG$4:$AL$132,6,FALSE) -> 0 | BT15: =IFERROR(BR15-BS15,"-") -> 0.89514066 | BV15: {=_xlfn.XLOOKUP( $B$4&" "&$B15, Actuals!$D:$D, _xlfn.XLOOKUP( BV$6, Actuals!$H$3:$BM$3, Actuals!$H:$BM ) )}
B17: Story Point Breakout %
B18: Product | C18: In-period | D18: =VLOOKUP($B$4&" "&$B18,Actuals!$D$4:$AG$131,3,FALSE) -> % | E18: {=_xlfn.XLOOKUP( $B$4&" "&$B18, Actuals!$D:$D, _xlfn.XLOOKUP( E$6, Actuals!$H$3:$BD$3, Actuals!$H:$BD ) )} -> 1 | F18: {=_xlfn.XLOOKUP( $B$4&" "&$B18, Actuals!$D:$D, _xlfn.XLOOKUP( F$6, Actuals!$H$3:$BD$3, Actuals!$H:$BD ) )} -> 1 | G18: {=_xlfn.XLOOKUP( $B$4&" "&$B18, Actuals!$D:$D, _xlfn.XLOOKUP( G$6, Actuals!$H$3:$BD$3, Actuals!$H:$BD ) )} -> 1 | H18: {=_xlfn.XLOOKUP( $B$4&" "&$B18, Actuals!$D:$D, _xlfn.XLOOKUP( H$6, Actuals!$H$3:$BD$3, Actuals!$H:$BD ) )} -> 0.95 | I18: {=_xlfn.XLOOKUP( $B$4&" "&$B18, Actuals!$D:$D, _xlfn.XLOOKUP( I$6, Actuals!$H$3:$BD$3, Actuals!$H:$BD ) )} -> 0.97 | J18: {=_xlfn.XLOOKUP( $B$4&" "&$B18, Actuals!$D:$D, _xlfn.XLOOKUP( J$6, Actuals!$H$3:$BD$3, Actuals!$H:$BD ) )} -> 0.98 | K18: {=_xlfn.XLOOKUP( $B$4&" "&$B18, Actuals!$D:$D, _xlfn.XLOOKUP( K$6, Actuals!$H$3:$BD$3, Actuals!$H:$BD ) )} -> 0.98 | L18: {=_xlfn.XLOOKUP( $B$4&" "&$B18, Actuals!$D:$D, _xlfn.XLOOKUP( L$6, Actuals!$H$3:$BD$3, Actuals!$H:$BD ) )} -> 0.98 | ... AZ18: {=_xlfn.XLOOKUP( $B$4&" "&$B18, Actuals!$D:$D, _xlfn.XLOOKUP( AZ$6, Actuals!$H$3:$BD$3, Actuals!$H:$BD ) )} -> 0 | BB18: {=_xlfn.XLOOKUP( $B$4&" "&$B18, Actuals!$D:$D, _xlfn.XLOOKUP( BB$7, Actuals!$H$3:$BM$3, Actuals!$H:$BM ) )} -> 0.75 | BC18: =VLOOKUP($B$4&" "&$B18,Budget!$AG$4:$AL$132,$BB$5+1,FALSE) -> 0.95 | BD18: =IFERROR(BB18-BC18,"-") -> -0.2 | BF18: {=_xlfn.XLOOKUP( $B$4&" "&$B18, Actuals!$D:$D, _xlfn.XLOOKUP( BF$7, Actuals!$H$3:$BM$3, Actuals!$H:$BM ) )} -> - | BG18: =VLOOKUP($B$4&" "&$B18,Budget!$AG$4:$AL$132,BF$5+1,FALSE) -> 0.95 | BH18: =IFERROR(BF18-BG18,"-") -> - | BJ18: {=_xlfn.XLOOKUP( $B$4&" "&$B18, Actuals!$D:$D, _xlfn.XLOOKUP( BJ$7, Actuals!$H$3:$BM$3, Actuals!$H:$BM ) )} -> - | BK18: =VLOOKUP($B$4&" "&$B18,Budget!$AG$4:$AL$132,BJ$5+1,FALSE) -> 0.95 | BL18: =IFERROR(BJ18-BK18,"-") -> - | BN18: {=_xlfn.XLOOKUP( $B$4&" "&$B18, Actuals!$D:$D, _xlfn.XLOOKUP( BN$7, Actuals!$H$3:$BM$3, Actuals!$H:$BM ) )} -> - | BO18: =VLOOKUP($B$4&" "&$B18,Budget!$AG$4:$AL$132,BN$5+1,FALSE) -> 0.95 | BR18: {=_xlfn.XLOOKUP( $B$4&" "&$B18, Actuals!$D:$D, _xlfn.XLOOKUP( BR$6, Actuals!$H$3:$BM$3, Actuals!$H:$BM ) )} -> 0.125 | BS18: =VLOOKUP($B$4&" "&$B18,Budget!$AG$4:$AL$132,6,FALSE) -> 0.95 | BT18: =IFERROR(BR18-BS18,"-") -> -0.825 | BV18: {=_xlfn.XLOOKUP( $B$4&" "&$B18, Actuals!$D:$D, _xlfn.XLOOKUP( BV$6, Actuals!$H$3:$BM$3, Actuals!$H:$BM ) )} -> 0.81833333
B19: Maintenance / Internal | C19: In-period | D19: =VLOOKUP($B$4&" "&$B19,Actuals!$D$4:$AG$131,3,FALSE) -> % | E19: {=_xlfn.XLOOKUP( $B$4&" "&$B19, Actuals!$D:$D, _xlfn.XLOOKUP( E$6, Actuals!$H$3:$BD$3, Actuals!$H:$BD ) )} -> 0 | F19: {=_xlfn.XLOOKUP( $B$4&" "&$B19, Actuals!$D:$D, _xlfn.XLOOKUP( F$6, Actuals!$H$3:$BD$3, Actuals!$H:$BD ) )} -> 0 | G19: {=_xlfn.XLOOKUP( $B$4&" "&$B19, Actuals!$D:$D, _xlfn.XLOOKUP( G$6, Actuals!$H$3:$BD$3, Actuals!$H:$BD ) )} -> 0 | H19: {=_xlfn.XLOOKUP( $B$4&" "&$B19, Actuals!$D:$D, _xlfn.XLOOKUP( H$6, Actuals!$H$3:$BD$3, Actuals!$H:$BD ) )} -> 0.05 | I19: {=_xlfn.XLOOKUP( $B$4&" "&$B19, Actuals!$D:$D, _xlfn.XLOOKUP( I$6, Actuals!$H$3:$BD$3, Actuals!$H:$BD ) )} -> 0.03 | J19: {=_xlfn.XLOOKUP( $B$4&" "&$B19, Actuals!$D:$D, _xlfn.XLOOKUP( J$6, Actuals!$H$3:$BD$3, Actuals!$H:$BD ) )} -> 0.02 | K19: {=_xlfn.XLOOKUP( $B$4&" "&$B19, Actuals!$D:$D, _xlfn.XLOOKUP( K$6, Actuals!$H$3:$BD$3, Actuals!$H:$BD ) )} -> 0.02 | L19: {=_xlfn.XLOOKUP( $B$4&" "&$B19, Actuals!$D:$D, _xlfn.XLOOKUP( L$6, Actuals!$H$3:$BD$3, Actuals!$H:$BD ) )} -> 0.02 | ... AZ19: {=_xlfn.XLOOKUP( $B$4&" "&$B19, Actuals!$D:$D, _xlfn.XLOOKUP( AZ$6, Actuals!$H$3:$BD$3, Actuals!$H:$BD ) )} -> 0 | BB19: {=_xlfn.XLOOKUP( $B$4&" "&$B19, Actuals!$D:$D, _xlfn.XLOOKUP( BB$7, Actuals!$H$3:$BM$3, Actuals!$H:$BM ) )} -> 0.25 | BC19: =VLOOKUP($B$4&" "&$B19,Budget!$AG$4:$AL$132,$BB$5+1,FALSE) -> 0.05 | BD19: =IFERROR(BB19-BC19,"-") -> 0.2 | BF19: {=_xlfn.XLOOKUP( $B$4&" "&$B19, Actuals!$D:$D, _xlfn.XLOOKUP( BF$7, Actuals!$H$3:$BM$3, Actuals!$H:$BM ) )} -> - | BG19: =VLOOKUP($B$4&" "&$B19,Budget!$AG$4:$AL$132,BF$5+1,FALSE) -> 0.05 | BH19: =IFERROR(BF19-BG19,"-") -> - | BJ19: {=_xlfn.XLOOKUP( $B$4&" "&$B19, Actuals!$D:$D, _xlfn.XLOOKUP( BJ$7, Actuals!$H$3:$BM$3, Actuals!$H:$BM ) )} -> - | BK19: =VLOOKUP($B$4&" "&$B19,Budget!$AG$4:$AL$132,BJ$5+1,FALSE) -> 0.05 | BL19: =IFERROR(BJ19-BK19,"-") -> - | BN19: {=_xlfn.XLOOKUP( $B$4&" "&$B19, Actuals!$D:$D, _xlfn.XLOOKUP( BN$7, Actuals!$H$3:$BM$3, Actuals!$H:$BM ) )} -> - | BO19: =VLOOKUP($B$4&" "&$B19,Budget!$AG$4:$AL$132,BN$5+1,FALSE) -> 0.05 | BR19: {=_xlfn.XLOOKUP( $B$4&" "&$B19, Actuals!$D:$D, _xlfn.XLOOKUP( BR$6, Actuals!$H$3:$BM$3, Actuals!$H:$BM ) )} -> 0.041666667 | BS19: =VLOOKUP($B$4&" "&$B19,Budget!$AG$4:$AL$132,6,FALSE) -> 0.05 | BT19: =IFERROR(BR19-BS19,"-") -> -0.0083333333 | BV19: {=_xlfn.XLOOKUP( $B$4&" "&$B19, Actuals!$D:$D, _xlfn.XLOOKUP( BV$6, Actuals!$H$3:$BM$3, Actuals!$H:$BM ) )} -> 0.18166667
B21: Efficiency
B22: Headcount (Total) | C22: EoP | D22: =VLOOKUP($B$4&" "&$B22,Actuals!$D$4:$AG$131,3,FALSE) -> # | E22: {=_xlfn.XLOOKUP( $B$4&" "&$B22, Actuals!$D:$D, _xlfn.XLOOKUP( E$6, Actuals!$H$3:$BD$3, Actuals!$H:$BD ) )} -> 10 | F22: {=_xlfn.XLOOKUP( $B$4&" "&$B22, Actuals!$D:$D, _xlfn.XLOOKUP( F$6, Actuals!$H$3:$BD$3, Actuals!$H:$BD ) )} -> 11 | G22: {=_xlfn.XLOOKUP( $B$4&" "&$B22, Actuals!$D:$D, _xlfn.XLOOKUP( G$6, Actuals!$H$3:$BD$3, Actuals!$H:$BD ) )} -> 12 | H22: {=_xlfn.XLOOKUP( $B$4&" "&$B22, Actuals!$D:$D, _xlfn.XLOOKUP( H$6, Actuals!$H$3:$BD$3, Actuals!$H:$BD ) )} -> 12 | I22: {=_xlfn.XLOOKUP( $B$4&" "&$B22, Actuals!$D:$D, _xlfn.XLOOKUP( I$6, Actuals!$H$3:$BD$3, Actuals!$H:$BD ) )} -> 12 | J22: {=_xlfn.XLOOKUP( $B$4&" "&$B22, Actuals!$D:$D, _xlfn.XLOOKUP( J$6, Actuals!$H$3:$BD$3, Actuals!$H:$BD ) )} -> 14 | K22: {=_xlfn.XLOOKUP( $B$4&" "&$B22, Actuals!$D:$D, _xlfn.XLOOKUP( K$6, Actuals!$H$3:$BD$3, Actuals!$H:$BD ) )} -> 17 | L22: {=_xlfn.XLOOKUP( $B$4&" "&$B22, Actuals!$D:$D, _xlfn.XLOOKUP( L$6, Actuals!$H$3:$BD$3, Actuals!$H:$BD ) )} -> 17 | ... AZ22: {=_xlfn.XLOOKUP( $B$4&" "&$B22, Actuals!$D:$D, _xlfn.XLOOKUP( AZ$6, Actuals!$H$3:$BD$3, Actuals!$H:$BD ) )} -> 0 | BB22: {=_xlfn.XLOOKUP( $B$4&" "&$B22, Actuals!$D:$D, _xlfn.XLOOKUP( BB$7, Actuals!$H$3:$BM$3, Actuals!$H:$BM ) )} -> 0 | BC22: =VLOOKUP($B$4&" "&$B22,Budget!$AG$4:$AL$132,$BB$5+1,FALSE) -> 0 | BD22: =BB22-BC22 -> 0 | BF22: {=_xlfn.XLOOKUP( $B$4&" "&$B22, Actuals!$D:$D, _xlfn.XLOOKUP( BF$7, Actuals!$H$3:$BM$3, Actuals!$H:$BM ) )} -> 0 | BG22: =VLOOKUP($B$4&" "&$B22,Budget!$AG$4:$AL$132,BF$5+1,FALSE) -> 25 | BH22: =BF22-BG22 -> -25 | BJ22: {=_xlfn.XLOOKUP( $B$4&" "&$B22, Actuals!$D:$D, _xlfn.XLOOKUP( BJ$7, Actuals!$H$3:$BM$3, Actuals!$H:$BM ) )} -> 0 | BK22: =VLOOKUP($B$4&" "&$B22,Budget!$AG$4:$AL$132,BJ$5+1,FALSE) -> 25 | BL22: =BJ22-BK22 -> -25 | BN22: {=_xlfn.XLOOKUP( $B$4&" "&$B22, Actuals!$D:$D, _xlfn.XLOOKUP( BN$7, Actuals!$H$3:$BM$3, Actuals!$H:$BM ) )} -> 0 | BO22: =VLOOKUP($B$4&" "&$B22,Budget!$AG$4:$AL$132,BN$5+1,FALSE) -> 25 | BR22: {=_xlfn.XLOOKUP( $B$4&" "&$B22, Actuals!$D:$D, _xlfn.XLOOKUP( BR$6, Actuals!$H$3:$BM$3, Actuals!$H:$BM ) )} -> 0 | BS22: =VLOOKUP($B$4&" "&$B22,Budget!$AG$4:$AL$132,6,FALSE) -> 25 | BT22: =IFERROR(BR22-BS22,"-") -> -25 | BV22: {=_xlfn.XLOOKUP( $B$4&" "&$B22, Actuals!$D:$D, _xlfn.XLOOKUP( BV$6, Actuals!$H$3:$BM$3, Actuals!$H:$BM ) )} -> 15
B23: Headcount - Squad - Onshore | C23: EoP | D23: =VLOOKUP($B$4&" "&$B23,Actuals!$D$4:$AG$131,3,FALSE) -> # | E23: {=_xlfn.XLOOKUP( $B$4&" "&$B23, Actuals!$D:$D, _xlfn.XLOOKUP( E$6, Actuals!$H$3:$BD$3, Actuals!$H:$BD ) )} -> 7 | F23: {=_xlfn.XLOOKUP( $B$4&" "&$B23, Actuals!$D:$D, _xlfn.XLOOKUP( F$6, Actuals!$H$3:$BD$3, Actuals!$H:$BD ) )} -> 6 | G23: {=_xlfn.XLOOKUP( $B$4&" "&$B23, Actuals!$D:$D, _xlfn.XLOOKUP( G$6, Actuals!$H$3:$BD$3, Actuals!$H:$BD ) )} -> 7 | H23: {=_xlfn.XLOOKUP( $B$4&" "&$B23, Actuals!$D:$D, _xlfn.XLOOKUP( H$6, Actuals!$H$3:$BD$3, Actuals!$H:$BD ) )} -> 7 | I23: {=_xlfn.XLOOKUP( $B$4&" "&$B23, Actuals!$D:$D, _xlfn.XLOOKUP( I$6, Actuals!$H$3:$BD$3, Actuals!$H:$BD ) )} -> 7 | J23: {=_xlfn.XLOOKUP( $B$4&" "&$B23, Actuals!$D:$D, _xlfn.XLOOKUP( J$6, Actuals!$H$3:$BD$3, Actuals!$H:$BD ) )} -> 7 | K23: {=_xlfn.XLOOKUP( $B$4&" "&$B23, Actuals!$D:$D, _xlfn.XLOOKUP( K$6, Actuals!$H$3:$BD$3, Actuals!$H:$BD ) )} -> 8 | L23: {=_xlfn.XLOOKUP( $B$4&" "&$B23, Actuals!$D:$D, _xlfn.XLOOKUP( L$6, Actuals!$H$3:$BD$3, Actuals!$H:$BD ) )} -> 8 | ... AZ23: {=_xlfn.XLOOKUP( $B$4&" "&$B23, Actuals!$D:$D, _xlfn.XLOOKUP( AZ$6, Actuals!$H$3:$BD$3, Actuals!$H:$BD ) )} -> 0 | BB23: {=_xlfn.XLOOKUP( $B$4&" "&$B23, Actuals!$D:$D, _xlfn.XLOOKUP( BB$7, Actuals!$H$3:$BM$3, Actuals!$H:$BM ) )} -> 0 | BC23: =VLOOKUP($B$4&" "&$B23,Budget!$AG$4:$AL$132,$BB$5+1,FALSE) -> 0 | BD23: =BB23-BC23 -> 0 | BF23: {=_xlfn.XLOOKUP( $B$4&" "&$B23, Actuals!$D:$D, _xlfn.XLOOKUP( BF$7, Actuals!$H$3:$BM$3, Actuals!$H:$BM ) )} -> 0 | BG23: =VLOOKUP($B$4&" "&$B23,Budget!$AG$4:$AL$132,BF$5+1,FALSE) -> 12 | BH23: =BF23-BG23 -> -12 | BJ23: {=_xlfn.XLOOKUP( $B$4&" "&$B23, Actuals!$D:$D, _xlfn.XLOOKUP( BJ$7, Actuals!$H$3:$BM$3, Actuals!$H:$BM ) )} -> 0 | BK23: =VLOOKUP($B$4&" "&$B23,Budget!$AG$4:$AL$132,BJ$5+1,FALSE) -> 12 | BL23: =BJ23-BK23 -> -12 | BN23: {=_xlfn.XLOOKUP( $B$4&" "&$B23, Actuals!$D:$D, _xlfn.XLOOKUP( BN$7, Actuals!$H$3:$BM$3, Actuals!$H:$BM ) )} -> 0 | BO23: =VLOOKUP($B$4&" "&$B23,Budget!$AG$4:$AL$132,BN$5+1,FALSE) -> 12 | BR23: {=_xlfn.XLOOKUP( $B$4&" "&$B23, Actuals!$D:$D, _xlfn.XLOOKUP( BR$6, Actuals!$H$3:$BM$3, Actuals!$H:$BM ) )} -> 0 | BS23: =VLOOKUP($B$4&" "&$B23,Budget!$AG$4:$AL$132,6,FALSE) -> 12 | BT23: =IFERROR(BR23-BS23,"-") -> -12 | BV23: {=_xlfn.XLOOKUP( $B$4&" "&$B23, Actuals!$D:$D, _xlfn.XLOOKUP( BV$6, Actuals!$H$3:$BM$3, Actuals!$H:$BM ) )} -> 3
B24: Headcount - Squad - Offshore | C24: EoP | D24: =VLOOKUP($B$4&" "&$B24,Actuals!$D$4:$AG$131,3,FALSE) -> # | E24: {=_xlfn.XLOOKUP( $B$4&" "&$B24, Actuals!$D:$D, _xlfn.XLOOKUP( E$6, Actuals!$H$3:$BD$3, Actuals!$H:$BD ) )} -> 3 | F24: {=_xlfn.XLOOKUP( $B$4&" "&$B24, Actuals!$D:$D, _xlfn.XLOOKUP( F$6, Actuals!$H$3:$BD$3, Actuals!$H:$BD ) )} -> 5 | G24: {=_xlfn.XLOOKUP( $B$4&" "&$B24, Actuals!$D:$D, _xlfn.XLOOKUP( G$6, Actuals!$H$3:$BD$3, Actuals!$H:$BD ) )} -> 5 | H24: {=_xlfn.XLOOKUP( $B$4&" "&$B24, Actuals!$D:$D, _xlfn.XLOOKUP( H$6, Actuals!$H$3:$BD$3, Actuals!$H:$BD ) )} -> 5 | I24: {=_xlfn.XLOOKUP( $B$4&" "&$B24, Actuals!$D:$D, _xlfn.XLOOKUP( I$6, Actuals!$H$3:$BD$3, Actuals!$H:$BD ) )} -> 5 | J24: {=_xlfn.XLOOKUP( $B$4&" "&$B24, Actuals!$D:$D, _xlfn.XLOOKUP( J$6, Actuals!$H$3:$BD$3, Actuals!$H:$BD ) )} -> 7 | K24: {=_xlfn.XLOOKUP( $B$4&" "&$B24, Actuals!$D:$D, _xlfn.XLOOKUP( K$6, Actuals!$H$3:$BD$3, Actuals!$H:$BD ) )} -> 9 | L24: {=_xlfn.XLOOKUP( $B$4&" "&$B24, Actuals!$D:$D, _xlfn.XLOOKUP( L$6, Actuals!$H$3:$BD$3, Actuals!$H:$BD ) )} -> 9 | ... AZ24: {=_xlfn.XLOOKUP( $B$4&" "&$B24, Actuals!$D:$D, _xlfn.XLOOKUP( AZ$6, Actuals!$H$3:$BD$3, Actuals!$H:$BD ) )} -> 0 | BB24: {=_xlfn.XLOOKUP( $B$4&" "&$B24, Actuals!$D:$D, _xlfn.XLOOKUP( BB$7, Actuals!$H$3:$BM$3, Actuals!$H:$BM ) )} -> 0 | BC24: =VLOOKUP($B$4&" "&$B24,Budget!$AG$4:$AL$132,$BB$5+1,FALSE) -> 0 | BD24: =BB24-BC24 -> 0 | BF24: {=_xlfn.XLOOKUP( $B$4&" "&$B24, Actuals!$D:$D, _xlfn.XLOOKUP( BF$7, Actuals!$H$3:$BM$3, Actuals!$H:$BM ) )} -> 0 | BG24: =VLOOKUP($B$4&" "&$B24,Budget!$AG$4:$AL$132,BF$5+1,FALSE) -> 13 | BH24: =BF24-BG24 -> -13 | BJ24: {=_xlfn.XLOOKUP( $B$4&" "&$B24, Actuals!$D:$D, _xlfn.XLOOKUP( BJ$7, Actuals!$H$3:$BM$3, Actuals!$H:$BM ) )} -> 0 | BK24: =VLOOKUP($B$4&" "&$B24,Budget!$AG$4:$AL$132,BJ$5+1,FALSE) -> 13 | BL24: =BJ24-BK24 -> -13 | BN24: {=_xlfn.XLOOKUP( $B$4&" "&$B24, Actuals!$D:$D, _xlfn.XLOOKUP( BN$7, Actuals!$H$3:$BM$3, Actuals!$H:$BM ) )} -> 0 | BO24: =VLOOKUP($B$4&" "&$B24,Budget!$AG$4:$AL$132,BN$5+1,FALSE) -> 13 | BR24: {=_xlfn.XLOOKUP( $B$4&" "&$B24, Actuals!$D:$D, _xlfn.XLOOKUP( BR$6, Actuals!$H$3:$BM$3, Actuals!$H:$BM ) )} -> 0 | BS24: =VLOOKUP($B$4&" "&$B24,Budget!$AG$4:$AL$132,6,FALSE) -> 13 | BT24: =IFERROR(BR24-BS24,"-") -> -13 | BV24: {=_xlfn.XLOOKUP( $B$4&" "&$B24, Actuals!$D:$D, _xlfn.XLOOKUP( BV$6, Actuals!$H$3:$BM$3, Actuals!$H:$BM ) )} -> 12
B25: Headcount - Non-Squad | C25: EoP | D25: =VLOOKUP($B$4&" "&$B25,Actuals!$D$4:$AG$131,3,FALSE) -> # | E25: {=_xlfn.XLOOKUP( $B$4&" "&$B25, Actuals!$D:$D, _xlfn.XLOOKUP( E$6, Actuals!$H$3:$BD$3, Actuals!$H:$BD ) )} -> 0 | F25: {=_xlfn.XLOOKUP( $B$4&" "&$B25, Actuals!$D:$D, _xlfn.XLOOKUP( F$6, Actuals!$H$3:$BD$3, Actuals!$H:$BD ) )} -> 0 | G25: {=_xlfn.XLOOKUP( $B$4&" "&$B25, Actuals!$D:$D, _xlfn.XLOOKUP( G$6, Actuals!$H$3:$BD$3, Actuals!$H:$BD ) )} -> 0 | H25: {=_xlfn.XLOOKUP( $B$4&" "&$B25, Actuals!$D:$D, _xlfn.XLOOKUP( H$6, Actuals!$H$3:$BD$3, Actuals!$H:$BD ) )} -> 0 | I25: {=_xlfn.XLOOKUP( $B$4&" "&$B25, Actuals!$D:$D, _xlfn.XLOOKUP( I$6, Actuals!$H$3:$BD$3, Actuals!$H:$BD ) )} -> 0 | J25: {=_xlfn.XLOOKUP( $B$4&" "&$B25, Actuals!$D:$D, _xlfn.XLOOKUP( J$6, Actuals!$H$3:$BD$3, Actuals!$H:$BD ) )} -> 0 | K25: {=_xlfn.XLOOKUP( $B$4&" "&$B25, Actuals!$D:$D, _xlfn.XLOOKUP( K$6, Actuals!$H$3:$BD$3, Actuals!$H:$BD ) )} -> 0 | L25: {=_xlfn.XLOOKUP( $B$4&" "&$B25, Actuals!$D:$D, _xlfn.XLOOKUP( L$6, Actuals!$H$3:$BD$3, Actuals!$H:$BD ) )} -> 0 | ... AZ25: {=_xlfn.XLOOKUP( $B$4&" "&$B25, Actuals!$D:$D, _xlfn.XLOOKUP( AZ$6, Actuals!$H$3:$BD$3, Actuals!$H:$BD ) )} -> 0 | BB25: {=_xlfn.XLOOKUP( $B$4&" "&$B25, Actuals!$D:$D, _xlfn.XLOOKUP( BB$7, Actuals!$H$3:$BM$3, Actuals!$H:$BM ) )} -> 0 | BC25: =VLOOKUP($B$4&" "&$B25,Budget!$AG$4:$AL$132,$BB$5+1,FALSE) -> 0 | BD25: =BB25-BC25 -> 0 | BF25: {=_xlfn.XLOOKUP( $B$4&" "&$B25, Actuals!$D:$D, _xlfn.XLOOKUP( BF$7, Actuals!$H$3:$BM$3, Actuals!$H:$BM ) )} -> 0 | BG25: =VLOOKUP($B$4&" "&$B25,Budget!$AG$4:$AL$132,BF$5+1,FALSE) -> 0 | BH25: =BF25-BG25 -> 0 | BJ25: {=_xlfn.XLOOKUP( $B$4&" "&$B25, Actuals!$D:$D, _xlfn.XLOOKUP( BJ$7, Actuals!$H$3:$BM$3, Actuals!$H:$BM ) )} -> 0 | BK25: =VLOOKUP($B$4&" "&$B25,Budget!$AG$4:$AL$132,BJ$5+1,FALSE) -> 0 | BL25: =BJ25-BK25 -> 0 | BN25: {=_xlfn.XLOOKUP( $B$4&" "&$B25, Actuals!$D:$D, _xlfn.XLOOKUP( BN$7, Actuals!$H$3:$BM$3, Actuals!$H:$BM ) )} -> 0 | BO25: =VLOOKUP($B$4&" "&$B25,Budget!$AG$4:$AL$132,BN$5+1,FALSE) -> 0 | BR25: {=_xlfn.XLOOKUP( $B$4&" "&$B25, Actuals!$D:$D, _xlfn.XLOOKUP( BR$6, Actuals!$H$3:$BM$3, Actuals!$H:$BM ) )} -> 0 | BS25: =VLOOKUP($B$4&" "&$B25,Budget!$AG$4:$AL$132,6,FALSE) -> 0 | BT25: =IFERROR(BR25-BS25,"-") -> 0 | BV25: {=_xlfn.XLOOKUP( $B$4&" "&$B25, Actuals!$D:$D, _xlfn.XLOOKUP( BV$6, Actuals!$H$3:$BM$3, Actuals!$H:$BM ) )} -> 0
B26: Avg. Personnel Cost per Squad | C26: Avg | D26: =VLOOKUP($B$4&" "&$B26,Actuals!$D$4:$AG$131,3,FALSE) -> $ | E26: {=_xlfn.XLOOKUP( $B$4&" "&$B26, Actuals!$D:$D, _xlfn.XLOOKUP( E$6, Actuals!$H$3:$BD$3, Actuals!$H:$BD ) )} -> 69121.715 | F26: {=_xlfn.XLOOKUP( $B$4&" "&$B26, Actuals!$D:$D, _xlfn.XLOOKUP( F$6, Actuals!$H$3:$BD$3, Actuals!$H:$BD ) )} -> 72497.695 | G26: {=_xlfn.XLOOKUP( $B$4&" "&$B26, Actuals!$D:$D, _xlfn.XLOOKUP( G$6, Actuals!$H$3:$BD$3, Actuals!$H:$BD ) )} -> 74103.685 | H26: {=_xlfn.XLOOKUP( $B$4&" "&$B26, Actuals!$D:$D, _xlfn.XLOOKUP( H$6, Actuals!$H$3:$BD$3, Actuals!$H:$BD ) )} -> 72135.81 | I26: {=_xlfn.XLOOKUP( $B$4&" "&$B26, Actuals!$D:$D, _xlfn.XLOOKUP( I$6, Actuals!$H$3:$BD$3, Actuals!$H:$BD ) )} -> 70305.68 | J26: {=_xlfn.XLOOKUP( $B$4&" "&$B26, Actuals!$D:$D, _xlfn.XLOOKUP( J$6, Actuals!$H$3:$BD$3, Actuals!$H:$BD ) )} -> 77211.37 | K26: {=_xlfn.XLOOKUP( $B$4&" "&$B26, Actuals!$D:$D, _xlfn.XLOOKUP( K$6, Actuals!$H$3:$BD$3, Actuals!$H:$BD ) )} -> 57329.25 | L26: {=_xlfn.XLOOKUP( $B$4&" "&$B26, Actuals!$D:$D, _xlfn.XLOOKUP( L$6, Actuals!$H$3:$BD$3, Actuals!$H:$BD ) )} -> 59369.04 | ... AZ26: {=_xlfn.XLOOKUP( $B$4&" "&$B26, Actuals!$D:$D, _xlfn.XLOOKUP( AZ$6, Actuals!$H$3:$BD$3, Actuals!$H:$BD ) )} -> 0 | BB26: {=_xlfn.XLOOKUP( $B$4&" "&$B26, Actuals!$D:$D, _xlfn.XLOOKUP( BB$7, Actuals!$H$3:$BM$3, Actuals!$H:$BM ) )} -> 84656.972 | BC26: =VLOOKUP($B$4&" "&$B26,Budget!$AG$4:$AL$132,$BB$5+1,FALSE) -> 75549.333 | BD26: =IFERROR(BB26-BC26,"-") -> 9107.6388 | BF26: {=_xlfn.XLOOKUP( $B$4&" "&$B26, Actuals!$D:$D, _xlfn.XLOOKUP( BF$7, Actuals!$H$3:$BM$3, Actuals!$H:$BM ) )} -> - | BG26: =VLOOKUP($B$4&" "&$B26,Budget!$AG$4:$AL$132,BF$5+1,FALSE) -> 75549.333 | BH26: =IFERROR(BF26-BG26,"-") -> - | BJ26: {=_xlfn.XLOOKUP( $B$4&" "&$B26, Actuals!$D:$D, _xlfn.XLOOKUP( BJ$7, Actuals!$H$3:$BM$3, Actuals!$H:$BM ) )} -> - | BK26: =VLOOKUP($B$4&" "&$B26,Budget!$AG$4:$AL$132,BJ$5+1,FALSE) -> 76843.778 | BL26: =IFERROR(BJ26-BK26,"-") -> - | BN26: {=_xlfn.XLOOKUP( $B$4&" "&$B26, Actuals!$D:$D, _xlfn.XLOOKUP( BN$7, Actuals!$H$3:$BM$3, Actuals!$H:$BM ) )} -> - | BO26: =VLOOKUP($B$4&" "&$B26,Budget!$AG$4:$AL$132,BN$5+1,FALSE) -> 77566 | BR26: {=_xlfn.XLOOKUP( $B$4&" "&$B26, Actuals!$D:$D, _xlfn.XLOOKUP( BR$6, Actuals!$H$3:$BM$3, Actuals!$H:$BM ) )} -> 21164.243 | BS26: =VLOOKUP($B$4&" "&$B26,Budget!$AG$4:$AL$132,6,FALSE) -> 76545.167 | BT26: =IFERROR(BR26-BS26,"-") -> -55380.924 | BV26: {=_xlfn.XLOOKUP( $B$4&" "&$B26, Actuals!$D:$D, _xlfn.XLOOKUP( BV$6, Actuals!$H$3:$BM$3, Actuals!$H:$BM ) )} -> 101251.9
B27: P&T Overhead | C27: In-period | D27: =VLOOKUP($B$4&" "&$B27,Actuals!$D$4:$AG$131,3,FALSE) -> $ | E27: {=_xlfn.XLOOKUP( $B$4&" "&$B27, Actuals!$D:$D, _xlfn.XLOOKUP( E$6, Actuals!$H$3:$BD$3, Actuals!$H:$BD ) )} -> 3540.88 | F27: {=_xlfn.XLOOKUP( $B$4&" "&$B27, Actuals!$D:$D, _xlfn.XLOOKUP( F$6, Actuals!$H$3:$BD$3, Actuals!$H:$BD ) )} -> 12655.84 | G27: {=_xlfn.XLOOKUP( $B$4&" "&$B27, Actuals!$D:$D, _xlfn.XLOOKUP( G$6, Actuals!$H$3:$BD$3, Actuals!$H:$BD ) )} -> 5571.23 | H27: {=_xlfn.XLOOKUP( $B$4&" "&$B27, Actuals!$D:$D, _xlfn.XLOOKUP( H$6, Actuals!$H$3:$BD$3, Actuals!$H:$BD ) )} -> 3952.25 | I27: {=_xlfn.XLOOKUP( $B$4&" "&$B27, Actuals!$D:$D, _xlfn.XLOOKUP( I$6, Actuals!$H$3:$BD$3, Actuals!$H:$BD ) )} -> 7151.77 | J27: {=_xlfn.XLOOKUP( $B$4&" "&$B27, Actuals!$D:$D, _xlfn.XLOOKUP( J$6, Actuals!$H$3:$BD$3, Actuals!$H:$BD ) )} -> 3481.27 | K27: {=_xlfn.XLOOKUP( $B$4&" "&$B27, Actuals!$D:$D, _xlfn.XLOOKUP( K$6, Actuals!$H$3:$BD$3, Actuals!$H:$BD ) )} -> 28391.06 | L27: {=_xlfn.XLOOKUP( $B$4&" "&$B27, Actuals!$D:$D, _xlfn.XLOOKUP( L$6, Actuals!$H$3:$BD$3, Actuals!$H:$BD ) )} -> 3604.27 | ... AZ27: {=_xlfn.XLOOKUP( $B$4&" "&$B27, Actuals!$D:$D, _xlfn.XLOOKUP( AZ$6, Actuals!$H$3:$BD$3, Actuals!$H:$BD ) )} -> 0 | BB27: {=_xlfn.XLOOKUP( $B$4&" "&$B27, Actuals!$D:$D, _xlfn.XLOOKUP( BB$7, Actuals!$H$3:$BM$3, Actuals!$H:$BM ) )} -> 38869.1 | BC27: =VLOOKUP($B$4&" "&$B27,Budget!$AG$4:$AL$132,$BB$5+1,FALSE) -> 80112 | BD27: =BB27-BC27 -> -41242.9 | BF27: {=_xlfn.XLOOKUP( $B$4&" "&$B27, Actuals!$D:$D, _xlfn.XLOOKUP( BF$7, Actuals!$H$3:$BM$3, Actuals!$H:$BM ) )} -> 0 | BG27: =VLOOKUP($B$4&" "&$B27,Budget!$AG$4:$AL$132,BF$5+1,FALSE) -> 19044 | BH27: =BF27-BG27 -> -19044 | BJ27: {=_xlfn.XLOOKUP( $B$4&" "&$B27, Actuals!$D:$D, _xlfn.XLOOKUP( BJ$7, Actuals!$H$3:$BM$3, Actuals!$H:$BM ) )} -> 0 | BK27: =VLOOKUP($B$4&" "&$B27,Budget!$AG$4:$AL$132,BJ$5+1,FALSE) -> 30904 | BL27: =BJ27-BK27 -> -30904 | BN27: {=_xlfn.XLOOKUP( $B$4&" "&$B27, Actuals!$D:$D, _xlfn.XLOOKUP( BN$7, Actuals!$H$3:$BM$3, Actuals!$H:$BM ) )} -> 0 | BO27: =VLOOKUP($B$4&" "&$B27,Budget!$AG$4:$AL$132,BN$5+1,FALSE) -> 29584 | BR27: {=_xlfn.XLOOKUP( $B$4&" "&$B27, Actuals!$D:$D, _xlfn.XLOOKUP( BR$6, Actuals!$H$3:$BM$3, Actuals!$H:$BM ) )} -> 38869.1 | BS27: =VLOOKUP($B$4&" "&$B27,Budget!$AG$4:$AL$132,6,FALSE) -> 165824 | BT27: =IFERROR(BR27-BS27,"-") -> -126954.9 | BV27: {=_xlfn.XLOOKUP( $B$4&" "&$B27, Actuals!$D:$D, _xlfn.XLOOKUP( BV$6, Actuals!$H$3:$BM$3, Actuals!$H:$BM ) )} -> 104740.92

Sheet Sales
B2: ='2023 Control'!$C$3 -> Concertiv
B3: =('2024 Control'!$C$4)&" Reporting Package" -> December 2025 Reporting Package
B4: Sales
E5: Monthly | BB5: 1 | BF5: 2 | BJ5: 3 | BN5: 4 | BR5: YTD vs. Budget
D6: Units | E6: 44957 | F6: 44985 | G6: 45016 | H6: =EOMONTH(G6,1) -> 45046 | I6: =EOMONTH(H6,1) -> 45077 | J6: =EOMONTH(I6,1) -> 45107 | K6: =EOMONTH(J6,1) -> 45138 | L6: =EOMONTH(K6,1) -> 45169 | M6: =EOMONTH(L6,1) -> 45199 | N6: =EOMONTH(M6,1) -> 45230 | O6: =EOMONTH(N6,1) -> 45260 | ... AZ6: =EOMONTH(AY6,1) -> 46387 | BB6: Act | BC6: Bgt. | BD6: Diff. | BF6: Act | BG6: Bgt. | BH6: Diff. | BJ6: Act | BK6: Bgt. | BL6: Diff. | BN6: Act | BO6: Bgt. | BP6: Diff. | BR6: YTD | BS6: Bgt. | BT6: Diff. | BV6: LTM
BB7: Q1 | BF7: Q2 | BJ7: Q3 | BN7: Q4
B8: Sales ARR ($)
B9: New Logo ARR ($) | C9: In-period | D9: =VLOOKUP($B$4&" "&$B9,Actuals!$D$4:$AG$131,3,FALSE) -> $ | E9: {=_xlfn.XLOOKUP( $B$4&" "&$B9, Actuals!$D:$D, _xlfn.XLOOKUP( E$6, Actuals!$H$3:$BD$3, Actuals!$H:$BD ) )} -> 49000 | F9: {=_xlfn.XLOOKUP( $B$4&" "&$B9, Actuals!$D:$D, _xlfn.XLOOKUP( F$6, Actuals!$H$3:$BD$3, Actuals!$H:$BD ) )} -> 0 | G9: {=_xlfn.XLOOKUP( $B$4&" "&$B9, Actuals!$D:$D, _xlfn.XLOOKUP( G$6, Actuals!$H$3:$BD$3, Actuals!$H:$BD ) )} -> 67000 | H9: {=_xlfn.XLOOKUP( $B$4&" "&$B9, Actuals!$D:$D, _xlfn.XLOOKUP( H$6, Actuals!$H$3:$BD$3, Actuals!$H:$BD ) )} -> 6250 | I9: {=_xlfn.XLOOKUP( $B$4&" "&$B9, Actuals!$D:$D, _xlfn.XLOOKUP( I$6, Actuals!$H$3:$BD$3, Actuals!$H:$BD ) )} -> 0 | J9: {=_xlfn.XLOOKUP( $B$4&" "&$B9, Actuals!$D:$D, _xlfn.XLOOKUP( J$6, Actuals!$H$3:$BD$3, Actuals!$H:$BD ) )} -> 215055 | K9: {=_xlfn.XLOOKUP( $B$4&" "&$B9, Actuals!$D:$D, _xlfn.XLOOKUP( K$6, Actuals!$H$3:$BD$3, Actuals!$H:$BD ) )} -> 0 | L9: {=_xlfn.XLOOKUP( $B$4&" "&$B9, Actuals!$D:$D, _xlfn.XLOOKUP( L$6, Actuals!$H$3:$BD$3, Actuals!$H:$BD ) )} -> 362940 | ... AZ9: {=_xlfn.XLOOKUP( $B$4&" "&$B9, Actuals!$D:$D, _xlfn.XLOOKUP( AZ$6, Actuals!$H$3:$BD$3, Actuals!$H:$BD ) )} -> 0 | BB9: {=_xlfn.XLOOKUP( $B$4&" "&$B9, Actuals!$D:$D, _xlfn.XLOOKUP( BB$7, Actuals!$H$3:$BM$3, Actuals!$H:$BM ) )} -> 0 | BC9: =VLOOKUP($B$4&" "&$B9,Budget!$AG$4:$AL$132,$BB$5+1,FALSE) -> 320000 | BD9: =BB9-BC9 -> -320000 | BF9: {=_xlfn.XLOOKUP( $B$4&" "&$B9, Actuals!$D:$D, _xlfn.XLOOKUP( BF$7, Actuals!$H$3:$BM$3, Actuals!$H:$BM ) )} -> 0 | BG9: =VLOOKUP($B$4&" "&$B9,Budget!$AG$4:$AL$132,BF$5+1,FALSE) -> 450000 | BH9: =BF9-BG9 -> -450000 | BJ9: {=_xlfn.XLOOKUP( $B$4&" "&$B9, Actuals!$D:$D, _xlfn.XLOOKUP( BJ$7, Actuals!$H$3:$BM$3, Actuals!$H:$BM ) )} -> 0 | BK9: =VLOOKUP($B$4&" "&$B9,Budget!$AG$4:$AL$132,BJ$5+1,FALSE) -> 450000 | BL9: =BJ9-BK9 -> -450000 | BN9: {=_xlfn.XLOOKUP( $B$4&" "&$B9, Actuals!$D:$D, _xlfn.XLOOKUP( BN$7, Actuals!$H$3:$BM$3, Actuals!$H:$BM ) )} -> 0 | BO9: =VLOOKUP($B$4&" "&$B9,Budget!$AG$4:$AL$132,BN$5+1,FALSE) -> 580000 | BR9: {=_xlfn.XLOOKUP( $B$4&" "&$B9, Actuals!$D:$D, _xlfn.XLOOKUP( BR$6, Actuals!$H$3:$BM$3, Actuals!$H:$BM ) )} -> 0 | BS9: =VLOOKUP($B$4&" "&$B9,Budget!$AG$4:$AL$132,6,FALSE) -> 1800000 | BT9: =BR9-BS9 -> -1800000 | BV9: {=_xlfn.XLOOKUP( $B$4&" "&$B9, Actuals!$D:$D, _xlfn.XLOOKUP( BV$6, Actuals!$H$3:$BM$3, Actuals!$H:$BM ) )} -> 387500
B11: Pipeline Activity (in-period)
B12: Sales Generated Opps. | C12: In-period | D12: =VLOOKUP($B$4&" "&$B12,Actuals!$D$4:$AG$131,3,FALSE) -> # | E12: {=_xlfn.XLOOKUP( $B$4&" "&$B12, Actuals!$D:$D, _xlfn.XLOOKUP( E$6, Actuals!$H$3:$BD$3, Actuals!$H:$BD ) )} -> 3 | F12: {=_xlfn.XLOOKUP( $B$4&" "&$B12, Actuals!$D:$D, _xlfn.XLOOKUP( F$6, Actuals!$H$3:$BD$3, Actuals!$H:$BD ) )} -> 1 | G12: {=_xlfn.XLOOKUP( $B$4&" "&$B12, Actuals!$D:$D, _xlfn.XLOOKUP( G$6, Actuals!$H$3:$BD$3, Actuals!$H:$BD ) )} -> 2 | H12: {=_xlfn.XLOOKUP( $B$4&" "&$B12, Actuals!$D:$D, _xlfn.XLOOKUP( H$6, Actuals!$H$3:$BD$3, Actuals!$H:$BD ) )} -> 7 | I12: {=_xlfn.XLOOKUP( $B$4&" "&$B12, Actuals!$D:$D, _xlfn.XLOOKUP( I$6, Actuals!$H$3:$BD$3, Actuals!$H:$BD ) )} -> 12 | J12: {=_xlfn.XLOOKUP( $B$4&" "&$B12, Actuals!$D:$D, _xlfn.XLOOKUP( J$6, Actuals!$H$3:$BD$3, Actuals!$H:$BD ) )} -> 3 | K12: {=_xlfn.XLOOKUP( $B$4&" "&$B12, Actuals!$D:$D, _xlfn.XLOOKUP( K$6, Actuals!$H$3:$BD$3, Actuals!$H:$BD ) )} -> 5 | L12: {=_xlfn.XLOOKUP( $B$4&" "&$B12, Actuals!$D:$D, _xlfn.XLOOKUP( L$6, Actuals!$H$3:$BD$3, Actuals!$H:$BD ) )} -> 4 | ... AZ12: {=_xlfn.XLOOKUP( $B$4&" "&$B12, Actuals!$D:$D, _xlfn.XLOOKUP( AZ$6, Actuals!$H$3:$BD$3, Actuals!$H:$BD ) )} -> 0 | BB12: {=_xlfn.XLOOKUP( $B$4&" "&$B12, Actuals!$D:$D, _xlfn.XLOOKUP( BB$7, Actuals!$H$3:$BM$3, Actuals!$H:$BM ) )} -> 0 | BC12: =VLOOKUP($B$4&" "&$B12,Budget!$AG$4:$AL$132,$BB$5+1,FALSE) -> 0 | BD12: =BB12-BC12 -> 0 | BF12: {=_xlfn.XLOOKUP( $B$4&" "&$B12, Actuals!$D:$D, _xlfn.XLOOKUP( BF$7, Actuals!$H$3:$BM$3, Actuals!$H:$BM ) )} -> 0 | BG12: =VLOOKUP($B$4&" "&$B12,Budget!$AG$4:$AL$132,BF$5+1,FALSE) -> 0 | BH12: =BF12-BG12 -> 0 | BJ12: {=_xlfn.XLOOKUP( $B$4&" "&$B12, Actuals!$D:$D, _xlfn.XLOOKUP( BJ$7, Actuals!$H$3:$BM$3, Actuals!$H:$BM ) )} -> 0 | BK12: =VLOOKUP($B$4&" "&$B12,Budget!$AG$4:$AL$132,BJ$5+1,FALSE) -> 0 | BL12: =BJ12-BK12 -> 0 | BN12: {=_xlfn.XLOOKUP( $B$4&" "&$B12, Actuals!$D:$D, _xlfn.XLOOKUP( BN$7, Actuals!$H$3:$BM$3, Actuals!$H:$BM ) )} -> 0 | BO12: =VLOOKUP($B$4&" "&$B12,Budget!$AG$4:$AL$132,BN$5+1,FALSE) -> 0 | BR12: {=_xlfn.XLOOKUP( $B$4&" "&$B12, Actuals!$D:$D, _xlfn.XLOOKUP( BR$6, Actuals!$H$3:$BM$3, Actuals!$H:$BM ) )} -> 0 | BS12: =VLOOKUP($B$4&" "&$B12,Budget!$AG$4:$AL$132,6,FALSE) -> 0 | BT12: =BR12-BS12 -> 0 | BV12: {=_xlfn.XLOOKUP( $B$4&" "&$B12, Actuals!$D:$D, _xlfn.XLOOKUP( BV$6, Actuals!$H$3:$BM$3, Actuals!$H:$BM ) )} -> 64
B13: Marketing Generated Opps. | C13: In-period | D13: =VLOOKUP($B$4&" "&$B13,Actuals!$D$4:$AG$131,3,FALSE) -> # | E13: {=_xlfn.XLOOKUP( $B$4&" "&$B13, Actuals!$D:$D, _xlfn.XLOOKUP( E$6, Actuals!$H$3:$BD$3, Actuals!$H:$BD ) )} -> 5 | F13: {=_xlfn.XLOOKUP( $B$4&" "&$B13, Actuals!$D:$D, _xlfn.XLOOKUP( F$6, Actuals!$H$3:$BD$3, Actuals!$H:$BD ) )} -> 1 | G13: {=_xlfn.XLOOKUP( $B$4&" "&$B13, Actuals!$D:$D, _xlfn.XLOOKUP( G$6, Actuals!$H$3:$BD$3, Actuals!$H:$BD ) )} -> 2 | H13: {=_xlfn.XLOOKUP( $B$4&" "&$B13, Actuals!$D:$D, _xlfn.XLOOKUP( H$6, Actuals!$H$3:$BD$3, Actuals!$H:$BD ) )} -> 0 | I13: {=_xlfn.XLOOKUP( $B$4&" "&$B13, Actuals!$D:$D, _xlfn.XLOOKUP( I$6, Actuals!$H$3:$BD$3, Actuals!$H:$BD ) )} -> 3 | J13: {=_xlfn.XLOOKUP( $B$4&" "&$B13, Actuals!$D:$D, _xlfn.XLOOKUP( J$6, Actuals!$H$3:$BD$3, Actuals!$H:$BD ) )} -> 7 | K13: {=_xlfn.XLOOKUP( $B$4&" "&$B13, Actuals!$D:$D, _xlfn.XLOOKUP( K$6, Actuals!$H$3:$BD$3, Actuals!$H:$BD ) )} -> 4 | L13: {=_xlfn.XLOOKUP( $B$4&" "&$B13, Actuals!$D:$D, _xlfn.XLOOKUP( L$6, Actuals!$H$3:$BD$3, Actuals!$H:$BD ) )} -> 2 | ... AZ13: {=_xlfn.XLOOKUP( $B$4&" "&$B13, Actuals!$D:$D, _xlfn.XLOOKUP( AZ$6, Actuals!$H$3:$BD$3, Actuals!$H:$BD ) )} -> 0 | BB13: {=_xlfn.XLOOKUP( $B$4&" "&$B13, Actuals!$D:$D, _xlfn.XLOOKUP( BB$7, Actuals!$H$3:$BM$3, Actuals!$H:$BM ) )} -> 0 | BC13: =VLOOKUP($B$4&" "&$B13,Budget!$AG$4:$AL$132,$BB$5+1,FALSE) -> 60 | BD13: =BB13-BC13 -> -60 | BF13: {=_xlfn.XLOOKUP( $B$4&" "&$B13, Actuals!$D:$D, _xlfn.XLOOKUP( BF$7, Actuals!$H$3:$BM$3, Actuals!$H:$BM ) )} -> 0 | BG13: =VLOOKUP($B$4&" "&$B13,Budget!$AG$4:$AL$132,BF$5+1,FALSE) -> 60 | BH13: =BF13-BG13 -> -60 | BJ13: {=_xlfn.XLOOKUP( $B$4&" "&$B13, Actuals!$D:$D, _xlfn.XLOOKUP( BJ$7, Actuals!$H$3:$BM$3, Actuals!$H:$BM ) )} -> 0 | BK13: =VLOOKUP($B$4&" "&$B13,Budget!$AG$4:$AL$132,BJ$5+1,FALSE) -> 60 | BL13: =BJ13-BK13 -> -60 | BN13: {=_xlfn.XLOOKUP( $B$4&" "&$B13, Actuals!$D:$D, _xlfn.XLOOKUP( BN$7, Actuals!$H$3:$BM$3, Actuals!$H:$BM ) )} -> 0 | BO13: =VLOOKUP($B$4&" "&$B13,Budget!$AG$4:$AL$132,BN$5+1,FALSE) -> 60 | BR13: {=_xlfn.XLOOKUP( $B$4&" "&$B13, Actuals!$D:$D, _xlfn.XLOOKUP( BR$6, Actuals!$H$3:$BM$3, Actuals!$H:$BM ) )} -> 0 | BS13: =VLOOKUP($B$4&" "&$B13,Budget!$AG$4:$AL$132,6,FALSE) -> 240 | BT13: =BR13-BS13 -> -240 | BV13: {=_xlfn.XLOOKUP( $B$4&" "&$B13, Actuals!$D:$D, _xlfn.XLOOKUP( BV$6, Actuals!$H$3:$BM$3, Actuals!$H:$BM ) )} -> 48
B14: Referral Generated Opps. | C14: In-period | D14: =VLOOKUP($B$4&" "&$B14,Actuals!$D$4:$AG$131,3,FALSE) -> # | E14: {=_xlfn.XLOOKUP( $B$4&" "&$B14, Actuals!$D:$D, _xlfn.XLOOKUP( E$6, Actuals!$H$3:$BD$3, Actuals!$H:$BD ) )} -> 2 | F14: {=_xlfn.XLOOKUP( $B$4&" "&$B14, Actuals!$D:$D, _xlfn.XLOOKUP( F$6, Actuals!$H$3:$BD$3, Actuals!$H:$BD ) )} -> 0 | G14: {=_xlfn.XLOOKUP( $B$4&" "&$B14, Actuals!$D:$D, _xlfn.XLOOKUP( G$6, Actuals!$H$3:$BD$3, Actuals!$H:$BD ) )} -> 2 | H14: {=_xlfn.XLOOKUP( $B$4&" "&$B14, Actuals!$D:$D, _xlfn.XLOOKUP( H$6, Actuals!$H$3:$BD$3, Actuals!$H:$BD ) )} -> 0 | I14: {=_xlfn.XLOOKUP( $B$4&" "&$B14, Actuals!$D:$D, _xlfn.XLOOKUP( I$6, Actuals!$H$3:$BD$3, Actuals!$H:$BD ) )} -> 3 | J14: {=_xlfn.XLOOKUP( $B$4&" "&$B14, Actuals!$D:$D, _xlfn.XLOOKUP( J$6, Actuals!$H$3:$BD$3, Actuals!$H:$BD ) )} -> 1 | K14: {=_xlfn.XLOOKUP( $B$4&" "&$B14, Actuals!$D:$D, _xlfn.XLOOKUP( K$6, Actuals!$H$3:$BD$3, Actuals!$H:$BD ) )} -> 3 | L14: {=_xlfn.XLOOKUP( $B$4&" "&$B14, Actuals!$D:$D, _xlfn.XLOOKUP( L$6, Actuals!$H$3:$BD$3, Actuals!$H:$BD ) )} -> 2 | ... AZ14: {=_xlfn.XLOOKUP( $B$4&" "&$B14, Actuals!$D:$D, _xlfn.XLOOKUP( AZ$6, Actuals!$H$3:$BD$3, Actuals!$H:$BD ) )} -> 0 | BB14: {=_xlfn.XLOOKUP( $B$4&" "&$B14, Actuals!$D:$D, _xlfn.XLOOKUP( BB$7, Actuals!$H$3:$BM$3, Actuals!$H:$BM ) )} -> 0 | BC14: =VLOOKUP($B$4&" "&$B14,Budget!$AG$4:$AL$132,$BB$5+1,FALSE) -> 0 | BD14: =BB14-BC14 -> 0 | BF14: {=_xlfn.XLOOKUP( $B$4&" "&$B14, Actuals!$D:$D, _xlfn.XLOOKUP( BF$7, Actuals!$H$3:$BM$3, Actuals!$H:$BM ) )} -> 0 | BG14: =VLOOKUP($B$4&" "&$B14,Budget!$AG$4:$AL$132,BF$5+1,FALSE) -> 0 | BH14: =BF14-BG14 -> 0 | BJ14: {=_xlfn.XLOOKUP( $B$4&" "&$B14, Actuals!$D:$D, _xlfn.XLOOKUP( BJ$7, Actuals!$H$3:$BM$3, Actuals!$H:$BM ) )} -> 0 | BK14: =VLOOKUP($B$4&" "&$B14,Budget!$AG$4:$AL$132,BJ$5+1,FALSE) -> 0 | BL14: =BJ14-BK14 -> 0 | BN14: {=_xlfn.XLOOKUP( $B$4&" "&$B14, Actuals!$D:$D, _xlfn.XLOOKUP( BN$7, Actuals!$H$3:$BM$3, Actuals!$H:$BM ) )} -> 0 | BO14: =VLOOKUP($B$4&" "&$B14,Budget!$AG$4:$AL$132,BN$5+1,FALSE) -> 0 | BR14: {=_xlfn.XLOOKUP( $B$4&" "&$B14, Actuals!$D:$D, _xlfn.XLOOKUP( BR$6, Actuals!$H$3:$BM$3, Actuals!$H:$BM ) )} -> 0 | BS14: =VLOOKUP($B$4&" "&$B14,Budget!$AG$4:$AL$132,6,FALSE) -> 0 | BT14: =BR14-BS14 -> 0 | BV14: {=_xlfn.XLOOKUP( $B$4&" "&$B14, Actuals!$D:$D, _xlfn.XLOOKUP( BV$6, Actuals!$H$3:$BM$3, Actuals!$H:$BM ) )} -> 61
B15: New Pipeline Opportunities | C15: In-period | D15: =VLOOKUP($B$4&" "&$B15,Actuals!$D$4:$AG$131,3,FALSE) -> # | E15: {=_xlfn.XLOOKUP( $B$4&" "&$B15, Actuals!$D:$D, _xlfn.XLOOKUP( E$6, Actuals!$H$3:$BD$3, Actuals!$H:$BD ) )} -> 10 | F15: {=_xlfn.XLOOKUP( $B$4&" "&$B15, Actuals!$D:$D, _xlfn.XLOOKUP( F$6, Actuals!$H$3:$BD$3, Actuals!$H:$BD ) )} -> 2 | G15: {=_xlfn.XLOOKUP( $B$4&" "&$B15, Actuals!$D:$D, _xlfn.XLOOKUP( G$6, Actuals!$H$3:$BD$3, Actuals!$H:$BD ) )} -> 6 | H15: {=_xlfn.XLOOKUP( $B$4&" "&$B15, Actuals!$D:$D, _xlfn.XLOOKUP( H$6, Actuals!$H$3:$BD$3, Actuals!$H:$BD ) )} -> 7 | I15: {=_xlfn.XLOOKUP( $B$4&" "&$B15, Actuals!$D:$D, _xlfn.XLOOKUP( I$6, Actuals!$H$3:$BD$3, Actuals!$H:$BD ) )} -> 18 | J15: {=_xlfn.XLOOKUP( $B$4&" "&$B15, Actuals!$D:$D, _xlfn.XLOOKUP( J$6, Actuals!$H$3:$BD$3, Actuals!$H:$BD ) )} -> 11 | K15: {=_xlfn.XLOOKUP( $B$4&" "&$B15, Actuals!$D:$D, _xlfn.XLOOKUP( K$6, Actuals!$H$3:$BD$3, Actuals!$H:$BD ) )} -> 12 | L15: {=_xlfn.XLOOKUP( $B$4&" "&$B15, Actuals!$D:$D, _xlfn.XLOOKUP( L$6, Actuals!$H$3:$BD$3, Actuals!$H:$BD ) )} -> 8 | ... AZ15: {=_xlfn.XLOOKUP( $B$4&" "&$B15, Actuals!$D:$D, _xlfn.XLOOKUP( AZ$6, Actuals!$H$3:$BD$3, Actuals!$H:$BD ) )} -> 0 | BB15: {=_xlfn.XLOOKUP( $B$4&" "&$B15, Actuals!$D:$D, _xlfn.XLOOKUP( BB$7, Actuals!$H$3:$BM$3, Actuals!$H:$BM ) )} -> 0 | BC15: =VLOOKUP($B$4&" "&$B15,Budget!$AG$4:$AL$132,$BB$5+1,FALSE) -> 60 | BD15: =BB15-BC15 -> -60 | BF15: {=_xlfn.XLOOKUP( $B$4&" "&$B15, Actuals!$D:$D, _xlfn.XLOOKUP( BF$7, Actuals!$H$3:$BM$3, Actuals!$H:$BM ) )} -> 0 | BG15: =VLOOKUP($B$4&" "&$B15,Budget!$AG$4:$AL$132,BF$5+1,FALSE) -> 60 | BH15: =BF15-BG15 -> -60 | BJ15: {=_xlfn.XLOOKUP( $B$4&" "&$B15, Actuals!$D:$D, _xlfn.XLOOKUP( BJ$7, Actuals!$H$3:$BM$3, Actuals!$H:$BM ) )} -> 0 | BK15: =VLOOKUP($B$4&" "&$B15,Budget!$AG$4:$AL$132,BJ$5+1,FALSE) -> 60 | BL15: =BJ15-BK15 -> -60 | BN15: {=_xlfn.XLOOKUP( $B$4&" "&$B15, Actuals!$D:$D, _xlfn.XLOOKUP( BN$7, Actuals!$H$3:$BM$3, Actuals!$H:$BM ) )} -> 0 | BO15: =VLOOKUP($B$4&" "&$B15,Budget!$AG$4:$AL$132,BN$5+1,FALSE) -> 60 | BR15: {=_xlfn.XLOOKUP( $B$4&" "&$B15, Actuals!$D:$D, _xlfn.XLOOKUP( BR$6, Actuals!$H$3:$BM$3, Actuals!$H:$BM ) )} -> 0 | BS15: =VLOOKUP($B$4&" "&$B15,Budget!$AG$4:$AL$132,6,FALSE) -> 240 | BT15: =BR15-BS15 -> -240 | BV15: {=_xlfn.XLOOKUP( $B$4&" "&$B15, Actuals!$D:$D, _xlfn.XLOOKUP( BV$6, Actuals!$H$3:$BM$3, Actuals!$H:$BM ) )} -> 173
B16: Won | C16: In-period | D16: =VLOOKUP($B$4&" "&$B16,Actuals!$D$4:$AG$131,3,FALSE) -> # | E16: {=_xlfn.XLOOKUP( $B$4&" "&$B16, Actuals!$D:$D, _xlfn.XLOOKUP( E$6, Actuals!$H$3:$BD$3, Actuals!$H:$BD ) )} -> 1 | F16: {=_xlfn.XLOOKUP( $B$4&" "&$B16, Actuals!$D:$D, _xlfn.XLOOKUP( F$6, Actuals!$H$3:$BD$3, Actuals!$H:$BD ) )} -> 0 | G16: {=_xlfn.XLOOKUP( $B$4&" "&$B16, Actuals!$D:$D, _xlfn.XLOOKUP( G$6, Actuals!$H$3:$BD$3, Actuals!$H:$BD ) )} -> 1 | H16: {=_xlfn.XLOOKUP( $B$4&" "&$B16, Actuals!$D:$D, _xlfn.XLOOKUP( H$6, Actuals!$H$3:$BD$3, Actuals!$H:$BD ) )} -> 0 | I16: {=_xlfn.XLOOKUP( $B$4&" "&$B16, Actuals!$D:$D, _xlfn.XLOOKUP( I$6, Actuals!$H$3:$BD$3, Actuals!$H:$BD ) )} -> 0 | J16: {=_xlfn.XLOOKUP( $B$4&" "&$B16, Actuals!$D:$D, _xlfn.XLOOKUP( J$6, Actuals!$H$3:$BD$3, Actuals!$H:$BD ) )} -> 1 | K16: {=_xlfn.XLOOKUP( $B$4&" "&$B16, Actuals!$D:$D, _xlfn.XLOOKUP( K$6, Actuals!$H$3:$BD$3, Actuals!$H:$BD ) )} -> 0 | L16: {=_xlfn.XLOOKUP( $B$4&" "&$B16, Actuals!$D:$D, _xlfn.XLOOKUP( L$6, Actuals!$H$3:$BD$3, Actuals!$H:$BD ) )} -> 2 | ... AZ16: {=_xlfn.XLOOKUP( $B$4&" "&$B16, Actuals!$D:$D, _xlfn.XLOOKUP( AZ$6, Actuals!$H$3:$BD$3, Actuals!$H:$BD ) )} -> 0 | BB16: {=_xlfn.XLOOKUP( $B$4&" "&$B16, Actuals!$D:$D, _xlfn.XLOOKUP( BB$7, Actuals!$H$3:$BM$3, Actuals!$H:$BM ) )} -> 0 | BC16: =VLOOKUP($B$4&" "&$B16,Budget!$AG$4:$AL$132,$BB$5+1,FALSE) -> 4.2666667 | BD16: =BB16-BC16 -> -4.2666667 | BF16: {=_xlfn.XLOOKUP( $B$4&" "&$B16, Actuals!$D:$D, _xlfn.XLOOKUP( BF$7, Actuals!$H$3:$BM$3, Actuals!$H:$BM ) )} -> 0 | BG16: =VLOOKUP($B$4&" "&$B16,Budget!$AG$4:$AL$132,BF$5+1,FALSE) -> 6 | BH16: =BF16-BG16 -> -6 | BJ16: {=_xlfn.XLOOKUP( $B$4&" "&$B16, Actuals!$D:$D, _xlfn.XLOOKUP( BJ$7, Actuals!$H$3:$BM$3, Actuals!$H:$BM ) )} -> 0 | BK16: =VLOOKUP($B$4&" "&$B16,Budget!$AG$4:$AL$132,BJ$5+1,FALSE) -> 6 | BL16: =BJ16-BK16 -> -6 | BN16: {=_xlfn.XLOOKUP( $B$4&" "&$B16, Actuals!$D:$D, _xlfn.XLOOKUP( BN$7, Actuals!$H$3:$BM$3, Actuals!$H:$BM ) )} -> 0 | BO16: =VLOOKUP($B$4&" "&$B16,Budget!$AG$4:$AL$132,BN$5+1,FALSE) -> 7.7333333 | BR16: {=_xlfn.XLOOKUP( $B$4&" "&$B16, Actuals!$D:$D, _xlfn.XLOOKUP( BR$6, Actuals!$H$3:$BM$3, Actuals!$H:$BM ) )} -> 0 | BS16: =VLOOKUP($B$4&" "&$B16,Budget!$AG$4:$AL$132,6,FALSE) -> 24 | BT16: =BR16-BS16 -> -24 | BV16: {=_xlfn.XLOOKUP( $B$4&" "&$B16, Actuals!$D:$D, _xlfn.XLOOKUP( BV$6, Actuals!$H$3:$BM$3, Actuals!$H:$BM ) )} -> 22
B17: Lost + Nurture | C17: In-period | D17: =VLOOKUP($B$4&" "&$B17,Actuals!$D$4:$AG$131,3,FALSE) -> # | E17: {=_xlfn.XLOOKUP( $B$4&" "&$B17, Actuals!$D:$D, _xlfn.XLOOKUP( E$6, Actuals!$H$3:$BD$3, Actuals!$H:$BD ) )} -> 4 | F17: {=_xlfn.XLOOKUP( $B$4&" "&$B17, Actuals!$D:$D, _xlfn.XLOOKUP( F$6, Actuals!$H$3:$BD$3, Actuals!$H:$BD ) )} -> 8 | G17: {=_xlfn.XLOOKUP( $B$4&" "&$B17, Actuals!$D:$D, _xlfn.XLOOKUP( G$6, Actuals!$H$3:$BD$3, Actuals!$H:$BD ) )} -> 19 | H17: {=_xlfn.XLOOKUP( $B$4&" "&$B17, Actuals!$D:$D, _xlfn.XLOOKUP( H$6, Actuals!$H$3:$BD$3, Actuals!$H:$BD ) )} -> 3 | I17: {=_xlfn.XLOOKUP( $B$4&" "&$B17, Actuals!$D:$D, _xlfn.XLOOKUP( I$6, Actuals!$H$3:$BD$3, Actuals!$H:$BD ) )} -> 3 | J17: {=_xlfn.XLOOKUP( $B$4&" "&$B17, Actuals!$D:$D, _xlfn.XLOOKUP( J$6, Actuals!$H$3:$BD$3, Actuals!$H:$BD ) )} -> 11 | K17: {=_xlfn.XLOOKUP( $B$4&" "&$B17, Actuals!$D:$D, _xlfn.XLOOKUP( K$6, Actuals!$H$3:$BD$3, Actuals!$H:$BD ) )} -> 6 | L17: {=_xlfn.XLOOKUP( $B$4&" "&$B17, Actuals!$D:$D, _xlfn.XLOOKUP( L$6, Actuals!$H$3:$BD$3, Actuals!$H:$BD ) )} -> 11 | ... AZ17: {=_xlfn.XLOOKUP( $B$4&" "&$B17, Actuals!$D:$D, _xlfn.XLOOKUP( AZ$6, Actuals!$H$3:$BD$3, Actuals!$H:$BD ) )} -> 0 | BB17: {=_xlfn.XLOOKUP( $B$4&" "&$B17, Actuals!$D:$D, _xlfn.XLOOKUP( BB$7, Actuals!$H$3:$BM$3, Actuals!$H:$BM ) )} -> 0 | BC17: =VLOOKUP($B$4&" "&$B17,Budget!$AG$4:$AL$132,$BB$5+1,FALSE) -> 0 | BD17: =BB17-BC17 -> 0 | BF17: {=_xlfn.XLOOKUP( $B$4&" "&$B17, Actuals!$D:$D, _xlfn.XLOOKUP( BF$7, Actuals!$H$3:$BM$3, Actuals!$H:$BM ) )} -> 0 | BG17: =VLOOKUP($B$4&" "&$B17,Budget!$AG$4:$AL$132,BF$5+1,FALSE) -> 0 | BH17: =BF17-BG17 -> 0 | BJ17: {=_xlfn.XLOOKUP( $B$4&" "&$B17, Actuals!$D:$D, _xlfn.XLOOKUP( BJ$7, Actuals!$H$3:$BM$3, Actuals!$H:$BM ) )} -> 0 | BK17: =VLOOKUP($B$4&" "&$B17,Budget!$AG$4:$AL$132,BJ$5+1,FALSE) -> 0 | BL17: =BJ17-BK17 -> 0 | BN17: {=_xlfn.XLOOKUP( $B$4&" "&$B17, Actuals!$D:$D, _xlfn.XLOOKUP( BN$7, Actuals!$H$3:$BM$3, Actuals!$H:$BM ) )} -> 0 | BO17: =VLOOKUP($B$4&" "&$B17,Budget!$AG$4:$AL$132,BN$5+1,FALSE) -> 0 | BR17: {=_xlfn.XLOOKUP( $B$4&" "&$B17, Actuals!$D:$D, _xlfn.XLOOKUP( BR$6, Actuals!$H$3:$BM$3, Actuals!$H:$BM ) )} -> 0 | BS17: =VLOOKUP($B$4&" "&$B17,Budget!$AG$4:$AL$132,6,FALSE) -> 0 | BT17: =BR17-BS17 -> 0 | BV17: {=_xlfn.XLOOKUP( $B$4&" "&$B17, Actuals!$D:$D, _xlfn.XLOOKUP( BV$6, Actuals!$H$3:$BM$3, Actuals!$H:$BM ) )} -> 27
B18: Win rate: Total | C18: In-period | D18: =VLOOKUP($B$4&" "&$B18,Actuals!$D$4:$AG$131,3,FALSE) -> # | E18: {=_xlfn.XLOOKUP( $B$4&" "&$B18, Actuals!$D:$D, _xlfn.XLOOKUP( E$6, Actuals!$H$3:$BD$3, Actuals!$H:$BD ) )} -> 0.25 | F18: {=_xlfn.XLOOKUP( $B$4&" "&$B18, Actuals!$D:$D, _xlfn.XLOOKUP( F$6, Actuals!$H$3:$BD$3, Actuals!$H:$BD ) )} -> 0 | G18: {=_xlfn.XLOOKUP( $B$4&" "&$B18, Actuals!$D:$D, _xlfn.XLOOKUP( G$6, Actuals!$H$3:$BD$3, Actuals!$H:$BD ) )} -> 0.052631579 | H18: {=_xlfn.XLOOKUP( $B$4&" "&$B18, Actuals!$D:$D, _xlfn.XLOOKUP( H$6, Actuals!$H$3:$BD$3, Actuals!$H:$BD ) )} -> 0 | I18: {=_xlfn.XLOOKUP( $B$4&" "&$B18, Actuals!$D:$D, _xlfn.XLOOKUP( I$6, Actuals!$H$3:$BD$3, Actuals!$H:$BD ) )} -> 0 | J18: {=_xlfn.XLOOKUP( $B$4&" "&$B18, Actuals!$D:$D, _xlfn.XLOOKUP( J$6, Actuals!$H$3:$BD$3, Actuals!$H:$BD ) )} -> 0.090909091 | K18: {=_xlfn.XLOOKUP( $B$4&" "&$B18, Actuals!$D:$D, _xlfn.XLOOKUP( K$6, Actuals!$H$3:$BD$3, Actuals!$H:$BD ) )} -> 0 | L18: {=_xlfn.XLOOKUP( $B$4&" "&$B18, Actuals!$D:$D, _xlfn.XLOOKUP( L$6, Actuals!$H$3:$BD$3, Actuals!$H:$BD ) )} -> 0.18181818 | ... AZ18: {=_xlfn.XLOOKUP( $B$4&" "&$B18, Actuals!$D:$D, _xlfn.XLOOKUP( AZ$6, Actuals!$H$3:$BD$3, Actuals!$H:$BD ) )} -> #DIV/0! | BB18: {=_xlfn.XLOOKUP( $B$4&" "&$B18, Actuals!$D:$D, _xlfn.XLOOKUP( BB$7, Actuals!$H$3:$BM$3, Actuals!$H:$BM ) )} -> - | BC18: =IFERROR(VLOOKUP($B$4&" "&$B18,Budget!$AG$4:$AL$132,$BB$5+1,FALSE),"n.a.") -> - | BD18: =IFERROR(BB18-BC18,"-") -> - | BF18: {=_xlfn.XLOOKUP( $B$4&" "&$B18, Actuals!$D:$D, _xlfn.XLOOKUP( BF$7, Actuals!$H$3:$BM$3, Actuals!$H:$BM ) )} -> - | BG18: =IFERROR(VLOOKUP($B$4&" "&$B18,Budget!$AG$4:$AL$132,$BF$5+1,FALSE),"n.a.") -> - | BH18: =IFERROR(BF18-BG18,"-") -> - | BJ18: {=_xlfn.XLOOKUP( $B$4&" "&$B18, Actuals!$D:$D, _xlfn.XLOOKUP( BJ$7, Actuals!$H$3:$BM$3, Actuals!$H:$BM ) )} -> - | BK18: =IFERROR(VLOOKUP($B$4&" "&$B18,Budget!$AG$4:$AL$132,$BJ$5+1,FALSE),"n.a.") -> - | BL18: =IFERROR(BJ18-BK18,"-") -> - | BN18: {=_xlfn.XLOOKUP( $B$4&" "&$B18, Actuals!$D:$D, _xlfn.XLOOKUP( BN$7, Actuals!$H$3:$BM$3, Actuals!$H:$BM ) )} -> - | BO18: =IFERROR(VLOOKUP($B$4&" "&$B18,Budget!$AG$4:$AL$132,$BN$5+1,FALSE),"n.a.") -> - | BR18: {=_xlfn.XLOOKUP( $B$4&" "&$B18, Actuals!$D:$D, _xlfn.XLOOKUP( BR$6, Actuals!$H$3:$BM$3, Actuals!$H:$BM ) )} -> #DIV/0! | BS18: =VLOOKUP($B$4&" "&$B18,Budget!$AG$4:$AL$132,6,FALSE) -> 0 | BT18: =BR18-BS18 -> #DIV/0! | BV18: {=_xlfn.XLOOKUP( $B$4&" "&$B18, Actuals!$D:$D, _xlfn.XLOOKUP( BV$6, Actuals!$H$3:$BM$3, Actuals!$H:$BM ) )} -> #DIV/0!
B19: Avg ACV | C19: In-period | D19: =VLOOKUP($B$4&" "&$B19,Actuals!$D$4:$AG$131,3,FALSE) -> # | E19: {=_xlfn.XLOOKUP( $B$4&" "&$B19, Actuals!$D:$D, _xlfn.XLOOKUP( E$6, Actuals!$H$3:$BD$3, Actuals!$H:$BD ) )} -> 49000 | F19: {=_xlfn.XLOOKUP( $B$4&" "&$B19, Actuals!$D:$D, _xlfn.XLOOKUP( F$6, Actuals!$H$3:$BD$3, Actuals!$H:$BD ) )} -> 0 | G19: {=_xlfn.XLOOKUP( $B$4&" "&$B19, Actuals!$D:$D, _xlfn.XLOOKUP( G$6, Actuals!$H$3:$BD$3, Actuals!$H:$BD ) )} -> 67000 | H19: {=_xlfn.XLOOKUP( $B$4&" "&$B19, Actuals!$D:$D, _xlfn.XLOOKUP( H$6, Actuals!$H$3:$BD$3, Actuals!$H:$BD ) )} -> 6250 | I19: {=_xlfn.XLOOKUP( $B$4&" "&$B19, Actuals!$D:$D, _xlfn.XLOOKUP( I$6, Actuals!$H$3:$BD$3, Actuals!$H:$BD ) )} -> 0 | J19: {=_xlfn.XLOOKUP( $B$4&" "&$B19, Actuals!$D:$D, _xlfn.XLOOKUP( J$6, Actuals!$H$3:$BD$3, Actuals!$H:$BD ) )} -> 198625 | K19: {=_xlfn.XLOOKUP( $B$4&" "&$B19, Actuals!$D:$D, _xlfn.XLOOKUP( K$6, Actuals!$H$3:$BD$3, Actuals!$H:$BD ) )} -> 0 | L19: {=_xlfn.XLOOKUP( $B$4&" "&$B19, Actuals!$D:$D, _xlfn.XLOOKUP( L$6, Actuals!$H$3:$BD$3, Actuals!$H:$BD ) )} -> 181300 | ... AZ19: {=_xlfn.XLOOKUP( $B$4&" "&$B19, Actuals!$D:$D, _xlfn.XLOOKUP( AZ$6, Actuals!$H$3:$BD$3, Actuals!$H:$BD ) )} -> 0 | BB19: {=_xlfn.XLOOKUP( $B$4&" "&$B19, Actuals!$D:$D, _xlfn.XLOOKUP( BB$7, Actuals!$H$3:$BM$3, Actuals!$H:$BM ) )} -> - | BC19: =IFERROR(VLOOKUP($B$4&" "&$B19,Budget!$AG$4:$AL$132,$BB$5+1,FALSE),"n.a.") -> 75000 | BD19: =IFERROR(BB19-BC19,"-") -> - | BF19: {=_xlfn.XLOOKUP( $B$4&" "&$B19, Actuals!$D:$D, _xlfn.XLOOKUP( BF$7, Actuals!$H$3:$BM$3, Actuals!$H:$BM ) )} -> - | BG19: =IFERROR(VLOOKUP($B$4&" "&$B19,Budget!$AG$4:$AL$132,$BF$5+1,FALSE),"n.a.") -> 75000 | BH19: =IFERROR(BF19-BG19,"-") -> - | BJ19: {=_xlfn.XLOOKUP( $B$4&" "&$B19, Actuals!$D:$D, _xlfn.XLOOKUP( BJ$7, Actuals!$H$3:$BM$3, Actuals!$H:$BM ) )} -> - | BK19: =IFERROR(VLOOKUP($B$4&" "&$B19,Budget!$AG$4:$AL$132,$BJ$5+1,FALSE),"n.a.") -> 75000 | BL19: =IFERROR(BJ19-BK19,"-") -> - | BN19: {=_xlfn.XLOOKUP( $B$4&" "&$B19, Actuals!$D:$D, _xlfn.XLOOKUP( BN$7, Actuals!$H$3:$BM$3, Actuals!$H:$BM ) )} -> - | BO19: =IFERROR(VLOOKUP($B$4&" "&$B19,Budget!$AG$4:$AL$132,$BN$5+1,FALSE),"n.a.") -> 75000 | BR19: {=_xlfn.XLOOKUP( $B$4&" "&$B19, Actuals!$D:$D, _xlfn.XLOOKUP( BR$6, Actuals!$H$3:$BM$3, Actuals!$H:$BM ) )} -> - | BS19: =VLOOKUP($B$4&" "&$B19,Budget!$AG$4:$AL$132,6,FALSE) -> 75000 | BT19: =BR19-BS19 -> #VALUE! | BV19: {=_xlfn.XLOOKUP( $B$4&" "&$B19, Actuals!$D:$D, _xlfn.XLOOKUP( BV$6, Actuals!$H$3:$BM$3, Actuals!$H:$BM ) )}
